Workbook
Name Arbeitspakete: Stammdaten!$H$32:$H$100
Name Austritt: Stammdaten!$D$17
Name Eintritt: Stammdaten!$D$15
Name Grund: Abwesenheit!$L$3:$L$13
Name Jahr: Stammdaten!$D$9
Name Projektnamen: Stammdaten!$B$32:$B$150

Sheet Übersicht
C2: ="Jahresübersicht "&Jahr&" der Zeitaufzeichnung von "&Stammdaten!$B$4&" für "&Stammdaten!$B$7 -> Jahresübersicht 2025 der Zeitaufzeichnung von Aya Helli für Research Institute AG & Co KG
B4: Tag | C4: =DATE(Jahr,COLUMN(C4)/3,1) -> 45658 | F4: =DATE(Jahr,COLUMN(F4)/3,1) -> 45689 | I4: =DATE(Jahr,COLUMN(I4)/3,1) -> 45717 | L4: =DATE(Jahr,COLUMN(L4)/3,1) -> 45748 | O4: =DATE(Jahr,COLUMN(O4)/3,1) -> 45778 | R4: =DATE(Jahr,COLUMN(R4)/3,1) -> 45809 | U4: =DATE(Jahr,COLUMN(U4)/3,1) -> 45839 | X4: =DATE(Jahr,COLUMN(X4)/3,1) -> 45870 | AA4: =DATE(Jahr,COLUMN(AA4)/3,1) -> 45901 | AD4: =DATE(Jahr,COLUMN(AD4)/3,1) -> 45931 | AG4: =DATE(Jahr,COLUMN(AG4)/3,1) -> 45962 | AJ4: =DATE(Jahr,COLUMN(AJ4)/3,1) -> 45992 | AM4: Tag
B5: 1 | C5: =DATE(Jahr,MONTH(C$4),$B5) -> 45658 | D5: =IF($B5>DAY(EOMONTH(C$4,0)),"",SUMIFS(INDIRECT(TEXT(C5,"MMM")&"!$L$9:$L$999"),INDIRECT(TEXT(C5,"MMM")&"!$B$9:$B$999"),C5)+SUMIFS(Abwesenheit!$J$3:$J$199,Abwesenheit!$D$3:$D$199,C5)) -> 0 | E5: =IF($B5>DAY(EOMONTH(C$4,0)),"",IF(OR(C5<IF(YEAR(Eintritt)<Jahr,DATE(Jahr,1,1),Eintritt),C5>IF(Austritt="",DATE(Jahr,12,31),Austritt)),0,IF(OR(ISERROR(VLOOKUP(C5,Stammdaten!$I$9:$J$26,2,FALSE)),SUMIFS(Stammdaten!$J$9:$J$26,Stammdaten!$I$9:$I$26,C5)=0),VLOOKUP(TEXT(C5,"TTT"),Stammdaten!$B$20:$F$26,5,FALSE),0))) -> 0 | F5: =DATE(Jahr,MONTH(F$4),$B5) -> 45689 | G5: =IF($B5>DAY(EOMONTH(F$4,0)),"",SUMIFS(INDIRECT(TEXT(F5,"MMM")&"!$L$9:$L$999"),INDIRECT(TEXT(F5,"MMM")&"!$B$9:$B$999"),F5)+SUMIFS(Abwesenheit!$J$3:$J$199,Abwesenheit!$D$3:$D$199,F5)) -> 0 | H5: =IF($B5>DAY(EOMONTH(F$4,0)),"",IF(OR(F5<IF(YEAR(Eintritt)<Jahr,DATE(Jahr,1,1),Eintritt),F5>IF(Austritt="",DATE(Jahr,12,31),Austritt)),0,IF(OR(ISERROR(VLOOKUP(F5,Stammdaten!$I$9:$J$26,2,FALSE)),SUMIFS(Stammdaten!$J$9:$J$26,Stammdaten!$I$9:$I$26,F5)=0),VLOOKUP(TEXT(F5,"TTT"),Stammdaten!$B$20:$F$26,5,FALSE),0))) -> 0 | I5: =DATE(Jahr,MONTH(I$4),$B5) -> 45717 | J5: =IF($B5>DAY(EOMONTH(I$4,0)),"",SUMIFS(INDIRECT(TEXT(I5,"MMM")&"!$L$9:$L$999"),INDIRECT(TEXT(I5,"MMM")&"!$B$9:$B$999"),I5)+SUMIFS(Abwesenheit!$J$3:$J$199,Abwesenheit!$D$3:$D$199,I5)) -> 0 | K5: =IF($B5>DAY(EOMONTH(I$4,0)),"",IF(OR(I5<IF(YEAR(Eintritt)<Jahr,DATE(Jahr,1,1),Eintritt),I5>IF(Austritt="",DATE(Jahr,12,31),Austritt)),0,IF(OR(ISERROR(VLOOKUP(I5,Stammdaten!$I$9:$J$26,2,FALSE)),SUMIFS(Stammdaten!$J$9:$J$26,Stammdaten!$I$9:$I$26,I5)=0),VLOOKUP(TEXT(I5,"TTT"),Stammdaten!$B$20:$F$26,5,FALSE),0))) -> 0 | L5: =DATE(Jahr,MONTH(L$4),$B5) -> 45748 | M5: =IF($B5>DAY(EOMONTH(L$4,0)),"",SUMIFS(INDIRECT(TEXT(L5,"MMM")&"!$L$9:$L$999"),INDIRECT(TEXT(L5,"MMM")&"!$B$9:$B$999"),L5)+SUMIFS(Abwesenheit!$J$3:$J$199,Abwesenheit!$D$3:$D$199,L5)) -> 0 | N5: =IF($B5>DAY(EOMONTH(L$4,0)),"",IF(OR(L5<IF(YEAR(Eintritt)<Jahr,DATE(Jahr,1,1),Eintritt),L5>IF(Austritt="",DATE(Jahr,12,31),Austritt)),0,IF(OR(ISERROR(VLOOKUP(L5,Stammdaten!$I$9:$J$26,2,FALSE)),SUMIFS(Stammdaten!$J$9:$J$26,Stammdaten!$I$9:$I$26,L5)=0),VLOOKUP(TEXT(L5,"TTT"),Stammdaten!$B$20:$F$26,5,FALSE),0))) -> 0 | O5: =DATE(Jahr,MONTH(O$4),$B5) -> 45778 | P5: =IF($B5>DAY(EOMONTH(O$4,0)),"",SUMIFS(INDIRECT(TEXT(O5,"MMM")&"!$L$9:$L$999"),INDIRECT(TEXT(O5,"MMM")&"!$B$9:$B$999"),O5)+SUMIFS(Abwesenheit!$J$3:$J$199,Abwesenheit!$D$3:$D$199,O5)) -> 0 | Q5: =IF($B5>DAY(EOMONTH(O$4,0)),"",IF(OR(O5<IF(YEAR(Eintritt)<Jahr,DATE(Jahr,1,1),Eintritt),O5>IF(Austritt="",DATE(Jahr,12,31),Austritt)),0,IF(OR(ISERROR(VLOOKUP(O5,Stammdaten!$I$9:$J$26,2,FALSE)),SUMIFS(Stammdaten!$J$9:$J$26,Stammdaten!$I$9:$I$26,O5)=0),VLOOKUP(TEXT(O5,"TTT"),Stammdaten!$B$20:$F$26,5,FALSE),0))) -> 0 | R5: =DATE(Jahr,MONTH(R$4),$B5) -> 45809 | S5: =IF($B5>DAY(EOMONTH(R$4,0)),"",SUMIFS(INDIRECT(TEXT(R5,"MMM")&"!$L$9:$L$999"),INDIRECT(TEXT(R5,"MMM")&"!$B$9:$B$999"),R5)+SUMIFS(Abwesenheit!$J$3:$J$199,Abwesenheit!$D$3:$D$199,R5)) -> 0 | T5: =IF($B5>DAY(EOMONTH(R$4,0)),"",IF(OR(R5<IF(YEAR(Eintritt)<Jahr,DATE(Jahr,1,1),Eintritt),R5>IF(Austritt="",DATE(Jahr,12,31),Austritt)),0,IF(OR(ISERROR(VLOOKUP(R5,Stammdaten!$I$9:$J$26,2,FALSE)),SUMIFS(Stammdaten!$J$9:$J$26,Stammdaten!$I$9:$I$26,R5)=0),VLOOKUP(TEXT(R5,"TTT"),Stammdaten!$B$20:$F$26,5,FALSE),0))) -> 0 | U5: =DATE(Jahr,MONTH(U$4),$B5) -> 45839 | V5: =IF($B5>DAY(EOMONTH(U$4,0)),"",SUMIFS(INDIRECT(TEXT(U5,"MMM")&"!$L$9:$L$999"),INDIRECT(TEXT(U5,"MMM")&"!$B$9:$B$999"),U5)+SUMIFS(Abwesenheit!$J$3:$J$199,Abwesenheit!$D$3:$D$199,U5)) -> 0 | W5: =IF($B5>DAY(EOMONTH(U$4,0)),"",IF(OR(U5<IF(YEAR(Eintritt)<Jahr,DATE(Jahr,1,1),Eintritt),U5>IF(Austritt="",DATE(Jahr,12,31),Austritt)),0,IF(OR(ISERROR(VLOOKUP(U5,Stammdaten!$I$9:$J$26,2,FALSE)),SUMIFS(Stammdaten!$J$9:$J$26,Stammdaten!$I$9:$I$26,U5)=0),VLOOKUP(TEXT(U5,"TTT"),Stammdaten!$B$20:$F$26,5,FALSE),0))) -> 0 | X5: =DATE(Jahr,MONTH(X$4),$B5) -> 45870 | Y5: =IF($B5>DAY(EOMONTH(X$4,0)),"",SUMIFS(INDIRECT(TEXT(X5,"MMM")&"!$L$9:$L$999"),INDIRECT(TEXT(X5,"MMM")&"!$B$9:$B$999"),X5)+SUMIFS(Abwesenheit!$J$3:$J$199,Abwesenheit!$D$3:$D$199,X5)) -> 0 | Z5: =IF($B5>DAY(EOMONTH(X$4,0)),"",IF(OR(X5<IF(YEAR(Eintritt)<Jahr,DATE(Jahr,1,1),Eintritt),X5>IF(Austritt="",DATE(Jahr,12,31),Austritt)),0,IF(OR(ISERROR(VLOOKUP(X5,Stammdaten!$I$9:$J$26,2,FALSE)),SUMIFS(Stammdaten!$J$9:$J$26,Stammdaten!$I$9:$I$26,X5)=0),VLOOKUP(TEXT(X5,"TTT"),Stammdaten!$B$20:$F$26,5,FALSE),0))) -> 0.33333333 | AA5: =DATE(Jahr,MONTH(AA$4),$B5) -> 45901 | AB5: =IF($B5>DAY(EOMONTH(AA$4,0)),"",SUMIFS(INDIRECT(TEXT(AA5,"MMM")&"!$L$9:$L$999"),INDIRECT(TEXT(AA5,"MMM")&"!$B$9:$B$999"),AA5)+SUMIFS(Abwesenheit!$J$3:$J$199,Abwesenheit!$D$3:$D$199,AA5)) -> 0 | AC5: =IF($B5>DAY(EOMONTH(AA$4,0)),"",IF(OR(AA5<IF(YEAR(Eintritt)<Jahr,DATE(Jahr,1,1),Eintritt),AA5>IF(Austritt="",DATE(Jahr,12,31),Austritt)),0,IF(OR(ISERROR(VLOOKUP(AA5,Stammdaten!$I$9:$J$26,2,FALSE)),SUMIFS(Stammdaten!$J$9:$J$26,Stammdaten!$I$9:$I$26,AA5)=0),VLOOKUP(TEXT(AA5,"TTT"),Stammdaten!$B$20:$F$26,5,FALSE),0))) -> 0 | AD5: =DATE(Jahr,MONTH(AD$4),$B5) -> 45931 | AE5: =IF($B5>DAY(EOMONTH(AD$4,0)),"",SUMIFS(INDIRECT(TEXT(AD5,"MMM")&"!$L$9:$L$999"),INDIRECT(TEXT(AD5,"MMM")&"!$B$9:$B$999"),AD5)+SUMIFS(Abwesenheit!$J$3:$J$199,Abwesenheit!$D$3:$D$199,AD5)) -> 0 | AF5: =IF($B5>DAY(EOMONTH(AD$4,0)),"",IF(OR(AD5<IF(YEAR(Eintritt)<Jahr,DATE(Jahr,1,1),Eintritt),AD5>IF(Austritt="",DATE(Jahr,12,31),Austritt)),0,IF(OR(ISERROR(VLOOKUP(AD5,Stammdaten!$I$9:$J$26,2,FALSE)),SUMIFS(Stammdaten!$J$9:$J$26,Stammdaten!$I$9:$I$26,AD5)=0),VLOOKUP(TEXT(AD5,"TTT"),Stammdaten!$B$20:$F$26,5,FALSE),0))) -> 0 | AG5: =DATE(Jahr,MONTH(AG$4),$B5) -> 45962 | AH5: =IF($B5>DAY(EOMONTH(AG$4,0)),"",SUMIFS(INDIRECT(TEXT(AG5,"MMM")&"!$L$9:$L$999"),INDIRECT(TEXT(AG5,"MMM")&"!$B$9:$B$999"),AG5)+SUMIFS(Abwesenheit!$J$3:$J$199,Abwesenheit!$D$3:$D$199,AG5)) -> 0 | AI5: =IF($B5>DAY(EOMONTH(AG$4,0)),"",IF(OR(AG5<IF(YEAR(Eintritt)<Jahr,DATE(Jahr,1,1),Eintritt),AG5>IF(Austritt="",DATE(Jahr,12,31),Austritt)),0,IF(OR(ISERROR(VLOOKUP(AG5,Stammdaten!$I$9:$J$26,2,FALSE)),SUMIFS(Stammdaten!$J$9:$J$26,Stammdaten!$I$9:$I$26,AG5)=0),VLOOKUP(TEXT(AG5,"TTT"),Stammdaten!$B$20:$F$26,5,FALSE),0))) -> 0 | AJ5: =DATE(Jahr,MONTH(AJ$4),$B5) -> 45992 | AK5: =IF($B5>DAY(EOMONTH(AJ$4,0)),"",SUMIFS(INDIRECT(TEXT(AJ5,"MMM")&"!$L$9:$L$999"),INDIRECT(TEXT(AJ5,"MMM")&"!$B$9:$B$999"),AJ5)+SUMIFS(Abwesenheit!$J$3:$J$199,Abwesenheit!$D$3:$D$199,AJ5)) -> 0 | AL5: =IF($B5>DAY(EOMONTH(AJ$4,0)),"",IF(OR(AJ5<IF(YEAR(Eintritt)<Jahr,DATE(Jahr,1,1),Eintritt),AJ5>IF(Austritt="",DATE(Jahr,12,31),Austritt)),0,VLOOKUP(TEXT(AJ5,"TTT"),Stammdaten!$B$20:$F$26,5,FALSE)-IF(ISERROR(VLOOKUP(AJ5,Stammdaten!$I$9:$J$26,2,FALSE)),0,SUMIFS(Stammdaten!$J$9:$J$26,Stammdaten!$I$9:$I$26,AJ5)/24))) -> 0 | AM5: 1
B6: 2 | C6: =DATE(Jahr,MONTH(C$4),$B6) -> 45659 | D6: =IF($B6>DAY(EOMONTH(C$4,0)),"",SUMIFS(INDIRECT(TEXT(C6,"MMM")&"!$L$9:$L$999"),INDIRECT(TEXT(C6,"MMM")&"!$B$9:$B$999"),C6)+SUMIFS(Abwesenheit!$J$3:$J$199,Abwesenheit!$D$3:$D$199,C6)) -> 0 | E6: =IF($B6>DAY(EOMONTH(C$4,0)),"",IF(OR(C6<IF(YEAR(Eintritt)<Jahr,DATE(Jahr,1,1),Eintritt),C6>IF(Austritt="",DATE(Jahr,12,31),Austritt)),0,IF(OR(ISERROR(VLOOKUP(C6,Stammdaten!$I$9:$J$26,2,FALSE)),SUMIFS(Stammdaten!$J$9:$J$26,Stammdaten!$I$9:$I$26,C6)=0),VLOOKUP(TEXT(C6,"TTT"),Stammdaten!$B$20:$F$26,5,FALSE),0))) -> 0 | F6: =DATE(Jahr,MONTH(F$4),$B6) -> 45690 | G6: =IF($B6>DAY(EOMONTH(F$4,0)),"",SUMIFS(INDIRECT(TEXT(F6,"MMM")&"!$L$9:$L$999"),INDIRECT(TEXT(F6,"MMM")&"!$B$9:$B$999"),F6)+SUMIFS(Abwesenheit!$J$3:$J$199,Abwesenheit!$D$3:$D$199,F6)) -> 0 | H6: =IF($B6>DAY(EOMONTH(F$4,0)),"",IF(OR(F6<IF(YEAR(Eintritt)<Jahr,DATE(Jahr,1,1),Eintritt),F6>IF(Austritt="",DATE(Jahr,12,31),Austritt)),0,IF(OR(ISERROR(VLOOKUP(F6,Stammdaten!$I$9:$J$26,2,FALSE)),SUMIFS(Stammdaten!$J$9:$J$26,Stammdaten!$I$9:$I$26,F6)=0),VLOOKUP(TEXT(F6,"TTT"),Stammdaten!$B$20:$F$26,5,FALSE),0))) -> 0 | I6: =DATE(Jahr,MONTH(I$4),$B6) -> 45718 | J6: =IF($B6>DAY(EOMONTH(I$4,0)),"",SUMIFS(INDIRECT(TEXT(I6,"MMM")&"!$L$9:$L$999"),INDIRECT(TEXT(I6,"MMM")&"!$B$9:$B$999"),I6)+SUMIFS(Abwesenheit!$J$3:$J$199,Abwesenheit!$D$3:$D$199,I6)) -> 0 | K6: =IF($B6>DAY(EOMONTH(I$4,0)),"",IF(OR(I6<IF(YEAR(Eintritt)<Jahr,DATE(Jahr,1,1),Eintritt),I6>IF(Austritt="",DATE(Jahr,12,31),Austritt)),0,IF(OR(ISERROR(VLOOKUP(I6,Stammdaten!$I$9:$J$26,2,FALSE)),SUMIFS(Stammdaten!$J$9:$J$26,Stammdaten!$I$9:$I$26,I6)=0),VLOOKUP(TEXT(I6,"TTT"),Stammdaten!$B$20:$F$26,5,FALSE),0))) -> 0 | L6: =DATE(Jahr,MONTH(L$4),$B6) -> 45749 | M6: =IF($B6>DAY(EOMONTH(L$4,0)),"",SUMIFS(INDIRECT(TEXT(L6,"MMM")&"!$L$9:$L$999"),INDIRECT(TEXT(L6,"MMM")&"!$B$9:$B$999"),L6)+SUMIFS(Abwesenheit!$J$3:$J$199,Abwesenheit!$D$3:$D$199,L6)) -> 0 | N6: =IF($B6>DAY(EOMONTH(L$4,0)),"",IF(OR(L6<IF(YEAR(Eintritt)<Jahr,DATE(Jahr,1,1),Eintritt),L6>IF(Austritt="",DATE(Jahr,12,31),Austritt)),0,IF(OR(ISERROR(VLOOKUP(L6,Stammdaten!$I$9:$J$26,2,FALSE)),SUMIFS(Stammdaten!$J$9:$J$26,Stammdaten!$I$9:$I$26,L6)=0),VLOOKUP(TEXT(L6,"TTT"),Stammdaten!$B$20:$F$26,5,FALSE),0))) -> 0 | O6: =DATE(Jahr,MONTH(O$4),$B6) -> 45779 | P6: =IF($B6>DAY(EOMONTH(O$4,0)),"",SUMIFS(INDIRECT(TEXT(O6,"MMM")&"!$L$9:$L$999"),INDIRECT(TEXT(O6,"MMM")&"!$B$9:$B$999"),O6)+SUMIFS(Abwesenheit!$J$3:$J$199,Abwesenheit!$D$3:$D$199,O6)) -> 0 | Q6: =IF($B6>DAY(EOMONTH(O$4,0)),"",IF(OR(O6<IF(YEAR(Eintritt)<Jahr,DATE(Jahr,1,1),Eintritt),O6>IF(Austritt="",DATE(Jahr,12,31),Austritt)),0,IF(OR(ISERROR(VLOOKUP(O6,Stammdaten!$I$9:$J$26,2,FALSE)),SUMIFS(Stammdaten!$J$9:$J$26,Stammdaten!$I$9:$I$26,O6)=0),VLOOKUP(TEXT(O6,"TTT"),Stammdaten!$B$20:$F$26,5,FALSE),0))) -> 0 | R6: =DATE(Jahr,MONTH(R$4),$B6) -> 45810 | S6: =IF($B6>DAY(EOMONTH(R$4,0)),"",SUMIFS(INDIRECT(TEXT(R6,"MMM")&"!$L$9:$L$999"),INDIRECT(TEXT(R6,"MMM")&"!$B$9:$B$999"),R6)+SUMIFS(Abwesenheit!$J$3:$J$199,Abwesenheit!$D$3:$D$199,R6)) -> 0 | T6: =IF($B6>DAY(EOMONTH(R$4,0)),"",IF(OR(R6<IF(YEAR(Eintritt)<Jahr,DATE(Jahr,1,1),Eintritt),R6>IF(Austritt="",DATE(Jahr,12,31),Austritt)),0,IF(OR(ISERROR(VLOOKUP(R6,Stammdaten!$I$9:$J$26,2,FALSE)),SUMIFS(Stammdaten!$J$9:$J$26,Stammdaten!$I$9:$I$26,R6)=0),VLOOKUP(TEXT(R6,"TTT"),Stammdaten!$B$20:$F$26,5,FALSE),0))) -> 0 | U6: =DATE(Jahr,MONTH(U$4),$B6) -> 45840 | V6: =IF($B6>DAY(EOMONTH(U$4,0)),"",SUMIFS(INDIRECT(TEXT(U6,"MMM")&"!$L$9:$L$999"),INDIRECT(TEXT(U6,"MMM")&"!$B$9:$B$999"),U6)+SUMIFS(Abwesenheit!$J$3:$J$199,Abwesenheit!$D$3:$D$199,U6)) -> 0 | W6: =IF($B6>DAY(EOMONTH(U$4,0)),"",IF(OR(U6<IF(YEAR(Eintritt)<Jahr,DATE(Jahr,1,1),Eintritt),U6>IF(Austritt="",DATE(Jahr,12,31),Austritt)),0,IF(OR(ISERROR(VLOOKUP(U6,Stammdaten!$I$9:$J$26,2,FALSE)),SUMIFS(Stammdaten!$J$9:$J$26,Stammdaten!$I$9:$I$26,U6)=0),VLOOKUP(TEXT(U6,"TTT"),Stammdaten!$B$20:$F$26,5,FALSE),0))) -> 0 | X6: =DATE(Jahr,MONTH(X$4),$B6) -> 45871 | Y6: =IF($B6>DAY(EOMONTH(X$4,0)),"",SUMIFS(INDIRECT(TEXT(X6,"MMM")&"!$L$9:$L$999"),INDIRECT(TEXT(X6,"MMM")&"!$B$9:$B$999"),X6)+SUMIFS(Abwesenheit!$J$3:$J$199,Abwesenheit!$D$3:$D$199,X6)) -> 0 | Z6: =IF($B6>DAY(EOMONTH(X$4,0)),"",IF(OR(X6<IF(YEAR(Eintritt)<Jahr,DATE(Jahr,1,1),Eintritt),X6>IF(Austritt="",DATE(Jahr,12,31),Austritt)),0,IF(OR(ISERROR(VLOOKUP(X6,Stammdaten!$I$9:$J$26,2,FALSE)),SUMIFS(Stammdaten!$J$9:$J$26,Stammdaten!$I$9:$I$26,X6)=0),VLOOKUP(TEXT(X6,"TTT"),Stammdaten!$B$20:$F$26,5,FALSE),0))) -> 0 | AA6: =DATE(Jahr,MONTH(AA$4),$B6) -> 45902 | AB6: =IF($B6>DAY(EOMONTH(AA$4,0)),"",SUMIFS(INDIRECT(TEXT(AA6,"MMM")&"!$L$9:$L$999"),INDIRECT(TEXT(AA6,"MMM")&"!$B$9:$B$999"),AA6)+SUMIFS(Abwesenheit!$J$3:$J$199,Abwesenheit!$D$3:$D$199,AA6)) -> 0 | AC6: =IF($B6>DAY(EOMONTH(AA$4,0)),"",IF(OR(AA6<IF(YEAR(Eintritt)<Jahr,DATE(Jahr,1,1),Eintritt),AA6>IF(Austritt="",DATE(Jahr,12,31),Austritt)),0,IF(OR(ISERROR(VLOOKUP(AA6,Stammdaten!$I$9:$J$26,2,FALSE)),SUMIFS(Stammdaten!$J$9:$J$26,Stammdaten!$I$9:$I$26,AA6)=0),VLOOKUP(TEXT(AA6,"TTT"),Stammdaten!$B$20:$F$26,5,FALSE),0))) -> 0 | AD6: =DATE(Jahr,MONTH(AD$4),$B6) -> 45932 | AE6: =IF($B6>DAY(EOMONTH(AD$4,0)),"",SUMIFS(INDIRECT(TEXT(AD6,"MMM")&"!$L$9:$L$999"),INDIRECT(TEXT(AD6,"MMM")&"!$B$9:$B$999"),AD6)+SUMIFS(Abwesenheit!$J$3:$J$199,Abwesenheit!$D$3:$D$199,AD6)) -> 0 | AF6: =IF($B6>DAY(EOMONTH(AD$4,0)),"",IF(OR(AD6<IF(YEAR(Eintritt)<Jahr,DATE(Jahr,1,1),Eintritt),AD6>IF(Austritt="",DATE(Jahr,12,31),Austritt)),0,IF(OR(ISERROR(VLOOKUP(AD6,Stammdaten!$I$9:$J$26,2,FALSE)),SUMIFS(Stammdaten!$J$9:$J$26,Stammdaten!$I$9:$I$26,AD6)=0),VLOOKUP(TEXT(AD6,"TTT"),Stammdaten!$B$20:$F$26,5,FALSE),0))) -> 0 | AG6: =DATE(Jahr,MONTH(AG$4),$B6) -> 45963 | AH6: =IF($B6>DAY(EOMONTH(AG$4,0)),"",SUMIFS(INDIRECT(TEXT(AG6,"MMM")&"!$L$9:$L$999"),INDIRECT(TEXT(AG6,"MMM")&"!$B$9:$B$999"),AG6)+SUMIFS(Abwesenheit!$J$3:$J$199,Abwesenheit!$D$3:$D$199,AG6)) -> 0 | AI6: =IF($B6>DAY(EOMONTH(AG$4,0)),"",IF(OR(AG6<IF(YEAR(Eintritt)<Jahr,DATE(Jahr,1,1),Eintritt),AG6>IF(Austritt="",DATE(Jahr,12,31),Austritt)),0,IF(OR(ISERROR(VLOOKUP(AG6,Stammdaten!$I$9:$J$26,2,FALSE)),SUMIFS(Stammdaten!$J$9:$J$26,Stammdaten!$I$9:$I$26,AG6)=0),VLOOKUP(TEXT(AG6,"TTT"),Stammdaten!$B$20:$F$26,5,FALSE),0))) -> 0 | AJ6: =DATE(Jahr,MONTH(AJ$4),$B6) -> 45993 | AK6: =IF($B6>DAY(EOMONTH(AJ$4,0)),"",SUMIFS(INDIRECT(TEXT(AJ6,"MMM")&"!$L$9:$L$999"),INDIRECT(TEXT(AJ6,"MMM")&"!$B$9:$B$999"),AJ6)+SUMIFS(Abwesenheit!$J$3:$J$199,Abwesenheit!$D$3:$D$199,AJ6)) -> 0 | AL6: =IF($B6>DAY(EOMONTH(AJ$4,0)),"",IF(OR(AJ6<IF(YEAR(Eintritt)<Jahr,DATE(Jahr,1,1),Eintritt),AJ6>IF(Austritt="",DATE(Jahr,12,31),Austritt)),0,VLOOKUP(TEXT(AJ6,"TTT"),Stammdaten!$B$20:$F$26,5,FALSE)-IF(ISERROR(VLOOKUP(AJ6,Stammdaten!$I$9:$J$26,2,FALSE)),0,SUMIFS(Stammdaten!$J$9:$J$26,Stammdaten!$I$9:$I$26,AJ6)/24))) -> 0 | AM6: 2
B7: 3 | C7: =DATE(Jahr,MONTH(C$4),$B7) -> 45660 | D7: =IF($B7>DAY(EOMONTH(C$4,0)),"",SUMIFS(INDIRECT(TEXT(C7,"MMM")&"!$L$9:$L$999"),INDIRECT(TEXT(C7,"MMM")&"!$B$9:$B$999"),C7)+SUMIFS(Abwesenheit!$J$3:$J$199,Abwesenheit!$D$3:$D$199,C7)) -> 0 | E7: =IF($B7>DAY(EOMONTH(C$4,0)),"",IF(OR(C7<IF(YEAR(Eintritt)<Jahr,DATE(Jahr,1,1),Eintritt),C7>IF(Austritt="",DATE(Jahr,12,31),Austritt)),0,IF(OR(ISERROR(VLOOKUP(C7,Stammdaten!$I$9:$J$26,2,FALSE)),SUMIFS(Stammdaten!$J$9:$J$26,Stammdaten!$I$9:$I$26,C7)=0),VLOOKUP(TEXT(C7,"TTT"),Stammdaten!$B$20:$F$26,5,FALSE),0))) -> 0 | F7: =DATE(Jahr,MONTH(F$4),$B7) -> 45691 | G7: =IF($B7>DAY(EOMONTH(F$4,0)),"",SUMIFS(INDIRECT(TEXT(F7,"MMM")&"!$L$9:$L$999"),INDIRECT(TEXT(F7,"MMM")&"!$B$9:$B$999"),F7)+SUMIFS(Abwesenheit!$J$3:$J$199,Abwesenheit!$D$3:$D$199,F7)) -> 0 | H7: =IF($B7>DAY(EOMONTH(F$4,0)),"",IF(OR(F7<IF(YEAR(Eintritt)<Jahr,DATE(Jahr,1,1),Eintritt),F7>IF(Austritt="",DATE(Jahr,12,31),Austritt)),0,IF(OR(ISERROR(VLOOKUP(F7,Stammdaten!$I$9:$J$26,2,FALSE)),SUMIFS(Stammdaten!$J$9:$J$26,Stammdaten!$I$9:$I$26,F7)=0),VLOOKUP(TEXT(F7,"TTT"),Stammdaten!$B$20:$F$26,5,FALSE),0))) -> 0 | I7: =DATE(Jahr,MONTH(I$4),$B7) -> 45719 | J7: =IF($B7>DAY(EOMONTH(I$4,0)),"",SUMIFS(INDIRECT(TEXT(I7,"MMM")&"!$L$9:$L$999"),INDIRECT(TEXT(I7,"MMM")&"!$B$9:$B$999"),I7)+SUMIFS(Abwesenheit!$J$3:$J$199,Abwesenheit!$D$3:$D$199,I7)) -> 0 | K7: =IF($B7>DAY(EOMONTH(I$4,0)),"",IF(OR(I7<IF(YEAR(Eintritt)<Jahr,DATE(Jahr,1,1),Eintritt),I7>IF(Austritt="",DATE(Jahr,12,31),Austritt)),0,IF(OR(ISERROR(VLOOKUP(I7,Stammdaten!$I$9:$J$26,2,FALSE)),SUMIFS(Stammdaten!$J$9:$J$26,Stammdaten!$I$9:$I$26,I7)=0),VLOOKUP(TEXT(I7,"TTT"),Stammdaten!$B$20:$F$26,5,FALSE),0))) -> 0 | L7: =DATE(Jahr,MONTH(L$4),$B7) -> 45750 | M7: =IF($B7>DAY(EOMONTH(L$4,0)),"",SUMIFS(INDIRECT(TEXT(L7,"MMM")&"!$L$9:$L$999"),INDIRECT(TEXT(L7,"MMM")&"!$B$9:$B$999"),L7)+SUMIFS(Abwesenheit!$J$3:$J$199,Abwesenheit!$D$3:$D$199,L7)) -> 0 | N7: =IF($B7>DAY(EOMONTH(L$4,0)),"",IF(OR(L7<IF(YEAR(Eintritt)<Jahr,DATE(Jahr,1,1),Eintritt),L7>IF(Austritt="",DATE(Jahr,12,31),Austritt)),0,IF(OR(ISERROR(VLOOKUP(L7,Stammdaten!$I$9:$J$26,2,FALSE)),SUMIFS(Stammdaten!$J$9:$J$26,Stammdaten!$I$9:$I$26,L7)=0),VLOOKUP(TEXT(L7,"TTT"),Stammdaten!$B$20:$F$26,5,FALSE),0))) -> 0 | O7: =DATE(Jahr,MONTH(O$4),$B7) -> 45780 | P7: =IF($B7>DAY(EOMONTH(O$4,0)),"",SUMIFS(INDIRECT(TEXT(O7,"MMM")&"!$L$9:$L$999"),INDIRECT(TEXT(O7,"MMM")&"!$B$9:$B$999"),O7)+SUMIFS(Abwesenheit!$J$3:$J$199,Abwesenheit!$D$3:$D$199,O7)) -> 0 | Q7: =IF($B7>DAY(EOMONTH(O$4,0)),"",IF(OR(O7<IF(YEAR(Eintritt)<Jahr,DATE(Jahr,1,1),Eintritt),O7>IF(Austritt="",DATE(Jahr,12,31),Austritt)),0,IF(OR(ISERROR(VLOOKUP(O7,Stammdaten!$I$9:$J$26,2,FALSE)),SUMIFS(Stammdaten!$J$9:$J$26,Stammdaten!$I$9:$I$26,O7)=0),VLOOKUP(TEXT(O7,"TTT"),Stammdaten!$B$20:$F$26,5,FALSE),0))) -> 0 | R7: =DATE(Jahr,MONTH(R$4),$B7) -> 45811 | S7: =IF($B7>DAY(EOMONTH(R$4,0)),"",SUMIFS(INDIRECT(TEXT(R7,"MMM")&"!$L$9:$L$999"),INDIRECT(TEXT(R7,"MMM")&"!$B$9:$B$999"),R7)+SUMIFS(Abwesenheit!$J$3:$J$199,Abwesenheit!$D$3:$D$199,R7)) -> 0 | T7: =IF($B7>DAY(EOMONTH(R$4,0)),"",IF(OR(R7<IF(YEAR(Eintritt)<Jahr,DATE(Jahr,1,1),Eintritt),R7>IF(Austritt="",DATE(Jahr,12,31),Austritt)),0,IF(OR(ISERROR(VLOOKUP(R7,Stammdaten!$I$9:$J$26,2,FALSE)),SUMIFS(Stammdaten!$J$9:$J$26,Stammdaten!$I$9:$I$26,R7)=0),VLOOKUP(TEXT(R7,"TTT"),Stammdaten!$B$20:$F$26,5,FALSE),0))) -> 0 | U7: =DATE(Jahr,MONTH(U$4),$B7) -> 45841 | V7: =IF($B7>DAY(EOMONTH(U$4,0)),"",SUMIFS(INDIRECT(TEXT(U7,"MMM")&"!$L$9:$L$999"),INDIRECT(TEXT(U7,"MMM")&"!$B$9:$B$999"),U7)+SUMIFS(Abwesenheit!$J$3:$J$199,Abwesenheit!$D$3:$D$199,U7)) -> 0 | W7: =IF($B7>DAY(EOMONTH(U$4,0)),"",IF(OR(U7<IF(YEAR(Eintritt)<Jahr,DATE(Jahr,1,1),Eintritt),U7>IF(Austritt="",DATE(Jahr,12,31),Austritt)),0,IF(OR(ISERROR(VLOOKUP(U7,Stammdaten!$I$9:$J$26,2,FALSE)),SUMIFS(Stammdaten!$J$9:$J$26,Stammdaten!$I$9:$I$26,U7)=0),VLOOKUP(TEXT(U7,"TTT"),Stammdaten!$B$20:$F$26,5,FALSE),0))) -> 0 | X7: =DATE(Jahr,MONTH(X$4),$B7) -> 45872 | Y7: =IF($B7>DAY(EOMONTH(X$4,0)),"",SUMIFS(INDIRECT(TEXT(X7,"MMM")&"!$L$9:$L$999"),INDIRECT(TEXT(X7,"MMM")&"!$B$9:$B$999"),X7)+SUMIFS(Abwesenheit!$J$3:$J$199,Abwesenheit!$D$3:$D$199,X7)) -> 0 | Z7: =IF($B7>DAY(EOMONTH(X$4,0)),"",IF(OR(X7<IF(YEAR(Eintritt)<Jahr,DATE(Jahr,1,1),Eintritt),X7>IF(Austritt="",DATE(Jahr,12,31),Austritt)),0,IF(OR(ISERROR(VLOOKUP(X7,Stammdaten!$I$9:$J$26,2,FALSE)),SUMIFS(Stammdaten!$J$9:$J$26,Stammdaten!$I$9:$I$26,X7)=0),VLOOKUP(TEXT(X7,"TTT"),Stammdaten!$B$20:$F$26,5,FALSE),0))) -> 0 | AA7: =DATE(Jahr,MONTH(AA$4),$B7) -> 45903 | AB7: =IF($B7>DAY(EOMONTH(AA$4,0)),"",SUMIFS(INDIRECT(TEXT(AA7,"MMM")&"!$L$9:$L$999"),INDIRECT(TEXT(AA7,"MMM")&"!$B$9:$B$999"),AA7)+SUMIFS(Abwesenheit!$J$3:$J$199,Abwesenheit!$D$3:$D$199,AA7)) -> 0 | AC7: =IF($B7>DAY(EOMONTH(AA$4,0)),"",IF(OR(AA7<IF(YEAR(Eintritt)<Jahr,DATE(Jahr,1,1),Eintritt),AA7>IF(Austritt="",DATE(Jahr,12,31),Austritt)),0,IF(OR(ISERROR(VLOOKUP(AA7,Stammdaten!$I$9:$J$26,2,FALSE)),SUMIFS(Stammdaten!$J$9:$J$26,Stammdaten!$I$9:$I$26,AA7)=0),VLOOKUP(TEXT(AA7,"TTT"),Stammdaten!$B$20:$F$26,5,FALSE),0))) -> 0 | AD7: =DATE(Jahr,MONTH(AD$4),$B7) -> 45933 | AE7: =IF($B7>DAY(EOMONTH(AD$4,0)),"",SUMIFS(INDIRECT(TEXT(AD7,"MMM")&"!$L$9:$L$999"),INDIRECT(TEXT(AD7,"MMM")&"!$B$9:$B$999"),AD7)+SUMIFS(Abwesenheit!$J$3:$J$199,Abwesenheit!$D$3:$D$199,AD7)) -> 0 | AF7: =IF($B7>DAY(EOMONTH(AD$4,0)),"",IF(OR(AD7<IF(YEAR(Eintritt)<Jahr,DATE(Jahr,1,1),Eintritt),AD7>IF(Austritt="",DATE(Jahr,12,31),Austritt)),0,IF(OR(ISERROR(VLOOKUP(AD7,Stammdaten!$I$9:$J$26,2,FALSE)),SUMIFS(Stammdaten!$J$9:$J$26,Stammdaten!$I$9:$I$26,AD7)=0),VLOOKUP(TEXT(AD7,"TTT"),Stammdaten!$B$20:$F$26,5,FALSE),0))) -> 0 | AG7: =DATE(Jahr,MONTH(AG$4),$B7) -> 45964 | AH7: =IF($B7>DAY(EOMONTH(AG$4,0)),"",SUMIFS(INDIRECT(TEXT(AG7,"MMM")&"!$L$9:$L$999"),INDIRECT(TEXT(AG7,"MMM")&"!$B$9:$B$999"),AG7)+SUMIFS(Abwesenheit!$J$3:$J$199,Abwesenheit!$D$3:$D$199,AG7)) -> 0 | AI7: =IF($B7>DAY(EOMONTH(AG$4,0)),"",IF(OR(AG7<IF(YEAR(Eintritt)<Jahr,DATE(Jahr,1,1),Eintritt),AG7>IF(Austritt="",DATE(Jahr,12,31),Austritt)),0,IF(OR(ISERROR(VLOOKUP(AG7,Stammdaten!$I$9:$J$26,2,FALSE)),SUMIFS(Stammdaten!$J$9:$J$26,Stammdaten!$I$9:$I$26,AG7)=0),VLOOKUP(TEXT(AG7,"TTT"),Stammdaten!$B$20:$F$26,5,FALSE),0))) -> 0 | AJ7: =DATE(Jahr,MONTH(AJ$4),$B7) -> 45994 | AK7: =IF($B7>DAY(EOMONTH(AJ$4,0)),"",SUMIFS(INDIRECT(TEXT(AJ7,"MMM")&"!$L$9:$L$999"),INDIRECT(TEXT(AJ7,"MMM")&"!$B$9:$B$999"),AJ7)+SUMIFS(Abwesenheit!$J$3:$J$199,Abwesenheit!$D$3:$D$199,AJ7)) -> 0 | AL7: =IF($B7>DAY(EOMONTH(AJ$4,0)),"",IF(OR(AJ7<IF(YEAR(Eintritt)<Jahr,DATE(Jahr,1,1),Eintritt),AJ7>IF(Austritt="",DATE(Jahr,12,31),Austritt)),0,VLOOKUP(TEXT(AJ7,"TTT"),Stammdaten!$B$20:$F$26,5,FALSE)-IF(ISERROR(VLOOKUP(AJ7,Stammdaten!$I$9:$J$26,2,FALSE)),0,SUMIFS(Stammdaten!$J$9:$J$26,Stammdaten!$I$9:$I$26,AJ7)/24))) -> 0 | AM7: 3
B8: 4 | C8: =DATE(Jahr,MONTH(C$4),$B8) -> 45661 | D8: =IF($B8>DAY(EOMONTH(C$4,0)),"",SUMIFS(INDIRECT(TEXT(C8,"MMM")&"!$L$9:$L$999"),INDIRECT(TEXT(C8,"MMM")&"!$B$9:$B$999"),C8)+SUMIFS(Abwesenheit!$J$3:$J$199,Abwesenheit!$D$3:$D$199,C8)) -> 0 | E8: =IF($B8>DAY(EOMONTH(C$4,0)),"",IF(OR(C8<IF(YEAR(Eintritt)<Jahr,DATE(Jahr,1,1),Eintritt),C8>IF(Austritt="",DATE(Jahr,12,31),Austritt)),0,IF(OR(ISERROR(VLOOKUP(C8,Stammdaten!$I$9:$J$26,2,FALSE)),SUMIFS(Stammdaten!$J$9:$J$26,Stammdaten!$I$9:$I$26,C8)=0),VLOOKUP(TEXT(C8,"TTT"),Stammdaten!$B$20:$F$26,5,FALSE),0))) -> 0 | F8: =DATE(Jahr,MONTH(F$4),$B8) -> 45692 | G8: =IF($B8>DAY(EOMONTH(F$4,0)),"",SUMIFS(INDIRECT(TEXT(F8,"MMM")&"!$L$9:$L$999"),INDIRECT(TEXT(F8,"MMM")&"!$B$9:$B$999"),F8)+SUMIFS(Abwesenheit!$J$3:$J$199,Abwesenheit!$D$3:$D$199,F8)) -> 0 | H8: =IF($B8>DAY(EOMONTH(F$4,0)),"",IF(OR(F8<IF(YEAR(Eintritt)<Jahr,DATE(Jahr,1,1),Eintritt),F8>IF(Austritt="",DATE(Jahr,12,31),Austritt)),0,IF(OR(ISERROR(VLOOKUP(F8,Stammdaten!$I$9:$J$26,2,FALSE)),SUMIFS(Stammdaten!$J$9:$J$26,Stammdaten!$I$9:$I$26,F8)=0),VLOOKUP(TEXT(F8,"TTT"),Stammdaten!$B$20:$F$26,5,FALSE),0))) -> 0 | I8: =DATE(Jahr,MONTH(I$4),$B8) -> 45720 | J8: =IF($B8>DAY(EOMONTH(I$4,0)),"",SUMIFS(INDIRECT(TEXT(I8,"MMM")&"!$L$9:$L$999"),INDIRECT(TEXT(I8,"MMM")&"!$B$9:$B$999"),I8)+SUMIFS(Abwesenheit!$J$3:$J$199,Abwesenheit!$D$3:$D$199,I8)) -> 0 | K8: =IF($B8>DAY(EOMONTH(I$4,0)),"",IF(OR(I8<IF(YEAR(Eintritt)<Jahr,DATE(Jahr,1,1),Eintritt),I8>IF(Austritt="",DATE(Jahr,12,31),Austritt)),0,IF(OR(ISERROR(VLOOKUP(I8,Stammdaten!$I$9:$J$26,2,FALSE)),SUMIFS(Stammdaten!$J$9:$J$26,Stammdaten!$I$9:$I$26,I8)=0),VLOOKUP(TEXT(I8,"TTT"),Stammdaten!$B$20:$F$26,5,FALSE),0))) -> 0 | L8: =DATE(Jahr,MONTH(L$4),$B8) -> 45751 | M8: =IF($B8>DAY(EOMONTH(L$4,0)),"",SUMIFS(INDIRECT(TEXT(L8,"MMM")&"!$L$9:$L$999"),INDIRECT(TEXT(L8,"MMM")&"!$B$9:$B$999"),L8)+SUMIFS(Abwesenheit!$J$3:$J$199,Abwesenheit!$D$3:$D$199,L8)) -> 0 | N8: =IF($B8>DAY(EOMONTH(L$4,0)),"",IF(OR(L8<IF(YEAR(Eintritt)<Jahr,DATE(Jahr,1,1),Eintritt),L8>IF(Austritt="",DATE(Jahr,12,31),Austritt)),0,IF(OR(ISERROR(VLOOKUP(L8,Stammdaten!$I$9:$J$26,2,FALSE)),SUMIFS(Stammdaten!$J$9:$J$26,Stammdaten!$I$9:$I$26,L8)=0),VLOOKUP(TEXT(L8,"TTT"),Stammdaten!$B$20:$F$26,5,FALSE),0))) -> 0 | O8: =DATE(Jahr,MONTH(O$4),$B8) -> 45781 | P8: =IF($B8>DAY(EOMONTH(O$4,0)),"",SUMIFS(INDIRECT(TEXT(O8,"MMM")&"!$L$9:$L$999"),INDIRECT(TEXT(O8,"MMM")&"!$B$9:$B$999"),O8)+SUMIFS(Abwesenheit!$J$3:$J$199,Abwesenheit!$D$3:$D$199,O8)) -> 0 | Q8: =IF($B8>DAY(EOMONTH(O$4,0)),"",IF(OR(O8<IF(YEAR(Eintritt)<Jahr,DATE(Jahr,1,1),Eintritt),O8>IF(Austritt="",DATE(Jahr,12,31),Austritt)),0,IF(OR(ISERROR(VLOOKUP(O8,Stammdaten!$I$9:$J$26,2,FALSE)),SUMIFS(Stammdaten!$J$9:$J$26,Stammdaten!$I$9:$I$26,O8)=0),VLOOKUP(TEXT(O8,"TTT"),Stammdaten!$B$20:$F$26,5,FALSE),0))) -> 0 | R8: =DATE(Jahr,MONTH(R$4),$B8) -> 45812 | S8: =IF($B8>DAY(EOMONTH(R$4,0)),"",SUMIFS(INDIRECT(TEXT(R8,"MMM")&"!$L$9:$L$999"),INDIRECT(TEXT(R8,"MMM")&"!$B$9:$B$999"),R8)+SUMIFS(Abwesenheit!$J$3:$J$199,Abwesenheit!$D$3:$D$199,R8)) -> 0 | T8: =IF($B8>DAY(EOMONTH(R$4,0)),"",IF(OR(R8<IF(YEAR(Eintritt)<Jahr,DATE(Jahr,1,1),Eintritt),R8>IF(Austritt="",DATE(Jahr,12,31),Austritt)),0,IF(OR(ISERROR(VLOOKUP(R8,Stammdaten!$I$9:$J$26,2,FALSE)),SUMIFS(Stammdaten!$J$9:$J$26,Stammdaten!$I$9:$I$26,R8)=0),VLOOKUP(TEXT(R8,"TTT"),Stammdaten!$B$20:$F$26,5,FALSE),0))) -> 0 | U8: =DATE(Jahr,MONTH(U$4),$B8) -> 45842 | V8: =IF($B8>DAY(EOMONTH(U$4,0)),"",SUMIFS(INDIRECT(TEXT(U8,"MMM")&"!$L$9:$L$999"),INDIRECT(TEXT(U8,"MMM")&"!$B$9:$B$999"),U8)+SUMIFS(Abwesenheit!$J$3:$J$199,Abwesenheit!$D$3:$D$199,U8)) -> 0 | W8: =IF($B8>DAY(EOMONTH(U$4,0)),"",IF(OR(U8<IF(YEAR(Eintritt)<Jahr,DATE(Jahr,1,1),Eintritt),U8>IF(Austritt="",DATE(Jahr,12,31),Austritt)),0,IF(OR(ISERROR(VLOOKUP(U8,Stammdaten!$I$9:$J$26,2,FALSE)),SUMIFS(Stammdaten!$J$9:$J$26,Stammdaten!$I$9:$I$26,U8)=0),VLOOKUP(TEXT(U8,"TTT"),Stammdaten!$B$20:$F$26,5,FALSE),0))) -> 0 | X8: =DATE(Jahr,MONTH(X$4),$B8) -> 45873 | Y8: =IF($B8>DAY(EOMONTH(X$4,0)),"",SUMIFS(INDIRECT(TEXT(X8,"MMM")&"!$L$9:$L$999"),INDIRECT(TEXT(X8,"MMM")&"!$B$9:$B$999"),X8)+SUMIFS(Abwesenheit!$J$3:$J$199,Abwesenheit!$D$3:$D$199,X8)) -> 0 | Z8: =IF($B8>DAY(EOMONTH(X$4,0)),"",IF(OR(X8<IF(YEAR(Eintritt)<Jahr,DATE(Jahr,1,1),Eintritt),X8>IF(Austritt="",DATE(Jahr,12,31),Austritt)),0,IF(OR(ISERROR(VLOOKUP(X8,Stammdaten!$I$9:$J$26,2,FALSE)),SUMIFS(Stammdaten!$J$9:$J$26,Stammdaten!$I$9:$I$26,X8)=0),VLOOKUP(TEXT(X8,"TTT"),Stammdaten!$B$20:$F$26,5,FALSE),0))) -> 0 | AA8: =DATE(Jahr,MONTH(AA$4),$B8) -> 45904 | AB8: =IF($B8>DAY(EOMONTH(AA$4,0)),"",SUMIFS(INDIRECT(TEXT(AA8,"MMM")&"!$L$9:$L$999"),INDIRECT(TEXT(AA8,"MMM")&"!$B$9:$B$999"),AA8)+SUMIFS(Abwesenheit!$J$3:$J$199,Abwesenheit!$D$3:$D$199,AA8)) -> 0 | AC8: =IF($B8>DAY(EOMONTH(AA$4,0)),"",IF(OR(AA8<IF(YEAR(Eintritt)<Jahr,DATE(Jahr,1,1),Eintritt),AA8>IF(Austritt="",DATE(Jahr,12,31),Austritt)),0,IF(OR(ISERROR(VLOOKUP(AA8,Stammdaten!$I$9:$J$26,2,FALSE)),SUMIFS(Stammdaten!$J$9:$J$26,Stammdaten!$I$9:$I$26,AA8)=0),VLOOKUP(TEXT(AA8,"TTT"),Stammdaten!$B$20:$F$26,5,FALSE),0))) -> 0 | AD8: =DATE(Jahr,MONTH(AD$4),$B8) -> 45934 | AE8: =IF($B8>DAY(EOMONTH(AD$4,0)),"",SUMIFS(INDIRECT(TEXT(AD8,"MMM")&"!$L$9:$L$999"),INDIRECT(TEXT(AD8,"MMM")&"!$B$9:$B$999"),AD8)+SUMIFS(Abwesenheit!$J$3:$J$199,Abwesenheit!$D$3:$D$199,AD8)) -> 0 | AF8: =IF($B8>DAY(EOMONTH(AD$4,0)),"",IF(OR(AD8<IF(YEAR(Eintritt)<Jahr,DATE(Jahr,1,1),Eintritt),AD8>IF(Austritt="",DATE(Jahr,12,31),Austritt)),0,IF(OR(ISERROR(VLOOKUP(AD8,Stammdaten!$I$9:$J$26,2,FALSE)),SUMIFS(Stammdaten!$J$9:$J$26,Stammdaten!$I$9:$I$26,AD8)=0),VLOOKUP(TEXT(AD8,"TTT"),Stammdaten!$B$20:$F$26,5,FALSE),0))) -> 0 | AG8: =DATE(Jahr,MONTH(AG$4),$B8) -> 45965 | AH8: =IF($B8>DAY(EOMONTH(AG$4,0)),"",SUMIFS(INDIRECT(TEXT(AG8,"MMM")&"!$L$9:$L$999"),INDIRECT(TEXT(AG8,"MMM")&"!$B$9:$B$999"),AG8)+SUMIFS(Abwesenheit!$J$3:$J$199,Abwesenheit!$D$3:$D$199,AG8)) -> 0 | AI8: =IF($B8>DAY(EOMONTH(AG$4,0)),"",IF(OR(AG8<IF(YEAR(Eintritt)<Jahr,DATE(Jahr,1,1),Eintritt),AG8>IF(Austritt="",DATE(Jahr,12,31),Austritt)),0,IF(OR(ISERROR(VLOOKUP(AG8,Stammdaten!$I$9:$J$26,2,FALSE)),SUMIFS(Stammdaten!$J$9:$J$26,Stammdaten!$I$9:$I$26,AG8)=0),VLOOKUP(TEXT(AG8,"TTT"),Stammdaten!$B$20:$F$26,5,FALSE),0))) -> 0 | AJ8: =DATE(Jahr,MONTH(AJ$4),$B8) -> 45995 | AK8: =IF($B8>DAY(EOMONTH(AJ$4,0)),"",SUMIFS(INDIRECT(TEXT(AJ8,"MMM")&"!$L$9:$L$999"),INDIRECT(TEXT(AJ8,"MMM")&"!$B$9:$B$999"),AJ8)+SUMIFS(Abwesenheit!$J$3:$J$199,Abwesenheit!$D$3:$D$199,AJ8)) -> 0 | AL8: =IF($B8>DAY(EOMONTH(AJ$4,0)),"",IF(OR(AJ8<IF(YEAR(Eintritt)<Jahr,DATE(Jahr,1,1),Eintritt),AJ8>IF(Austritt="",DATE(Jahr,12,31),Austritt)),0,VLOOKUP(TEXT(AJ8,"TTT"),Stammdaten!$B$20:$F$26,5,FALSE)-IF(ISERROR(VLOOKUP(AJ8,Stammdaten!$I$9:$J$26,2,FALSE)),0,SUMIFS(Stammdaten!$J$9:$J$26,Stammdaten!$I$9:$I$26,AJ8)/24))) -> 0 | AM8: 4
B9: 5 | C9: =DATE(Jahr,MONTH(C$4),$B9) -> 45662 | D9: =IF($B9>DAY(EOMONTH(C$4,0)),"",SUMIFS(INDIRECT(TEXT(C9,"MMM")&"!$L$9:$L$999"),INDIRECT(TEXT(C9,"MMM")&"!$B$9:$B$999"),C9)+SUMIFS(Abwesenheit!$J$3:$J$199,Abwesenheit!$D$3:$D$199,C9)) -> 0 | E9: =IF($B9>DAY(EOMONTH(C$4,0)),"",IF(OR(C9<IF(YEAR(Eintritt)<Jahr,DATE(Jahr,1,1),Eintritt),C9>IF(Austritt="",DATE(Jahr,12,31),Austritt)),0,IF(OR(ISERROR(VLOOKUP(C9,Stammdaten!$I$9:$J$26,2,FALSE)),SUMIFS(Stammdaten!$J$9:$J$26,Stammdaten!$I$9:$I$26,C9)=0),VLOOKUP(TEXT(C9,"TTT"),Stammdaten!$B$20:$F$26,5,FALSE),0))) -> 0 | F9: =DATE(Jahr,MONTH(F$4),$B9) -> 45693 | G9: =IF($B9>DAY(EOMONTH(F$4,0)),"",SUMIFS(INDIRECT(TEXT(F9,"MMM")&"!$L$9:$L$999"),INDIRECT(TEXT(F9,"MMM")&"!$B$9:$B$999"),F9)+SUMIFS(Abwesenheit!$J$3:$J$199,Abwesenheit!$D$3:$D$199,F9)) -> 0 | H9: =IF($B9>DAY(EOMONTH(F$4,0)),"",IF(OR(F9<IF(YEAR(Eintritt)<Jahr,DATE(Jahr,1,1),Eintritt),F9>IF(Austritt="",DATE(Jahr,12,31),Austritt)),0,IF(OR(ISERROR(VLOOKUP(F9,Stammdaten!$I$9:$J$26,2,FALSE)),SUMIFS(Stammdaten!$J$9:$J$26,Stammdaten!$I$9:$I$26,F9)=0),VLOOKUP(TEXT(F9,"TTT"),Stammdaten!$B$20:$F$26,5,FALSE),0))) -> 0 | I9: =DATE(Jahr,MONTH(I$4),$B9) -> 45721 | J9: =IF($B9>DAY(EOMONTH(I$4,0)),"",SUMIFS(INDIRECT(TEXT(I9,"MMM")&"!$L$9:$L$999"),INDIRECT(TEXT(I9,"MMM")&"!$B$9:$B$999"),I9)+SUMIFS(Abwesenheit!$J$3:$J$199,Abwesenheit!$D$3:$D$199,I9)) -> 0 | K9: =IF($B9>DAY(EOMONTH(I$4,0)),"",IF(OR(I9<IF(YEAR(Eintritt)<Jahr,DATE(Jahr,1,1),Eintritt),I9>IF(Austritt="",DATE(Jahr,12,31),Austritt)),0,IF(OR(ISERROR(VLOOKUP(I9,Stammdaten!$I$9:$J$26,2,FALSE)),SUMIFS(Stammdaten!$J$9:$J$26,Stammdaten!$I$9:$I$26,I9)=0),VLOOKUP(TEXT(I9,"TTT"),Stammdaten!$B$20:$F$26,5,FALSE),0))) -> 0 | L9: =DATE(Jahr,MONTH(L$4),$B9) -> 45752 | M9: =IF($B9>DAY(EOMONTH(L$4,0)),"",SUMIFS(INDIRECT(TEXT(L9,"MMM")&"!$L$9:$L$999"),INDIRECT(TEXT(L9,"MMM")&"!$B$9:$B$999"),L9)+SUMIFS(Abwesenheit!$J$3:$J$199,Abwesenheit!$D$3:$D$199,L9)) -> 0 | N9: =IF($B9>DAY(EOMONTH(L$4,0)),"",IF(OR(L9<IF(YEAR(Eintritt)<Jahr,DATE(Jahr,1,1),Eintritt),L9>IF(Austritt="",DATE(Jahr,12,31),Austritt)),0,IF(OR(ISERROR(VLOOKUP(L9,Stammdaten!$I$9:$J$26,2,FALSE)),SUMIFS(Stammdaten!$J$9:$J$26,Stammdaten!$I$9:$I$26,L9)=0),VLOOKUP(TEXT(L9,"TTT"),Stammdaten!$B$20:$F$26,5,FALSE),0))) -> 0 | O9: =DATE(Jahr,MONTH(O$4),$B9) -> 45782 | P9: =IF($B9>DAY(EOMONTH(O$4,0)),"",SUMIFS(INDIRECT(TEXT(O9,"MMM")&"!$L$9:$L$999"),INDIRECT(TEXT(O9,"MMM")&"!$B$9:$B$999"),O9)+SUMIFS(Abwesenheit!$J$3:$J$199,Abwesenheit!$D$3:$D$199,O9)) -> 0 | Q9: =IF($B9>DAY(EOMONTH(O$4,0)),"",IF(OR(O9<IF(YEAR(Eintritt)<Jahr,DATE(Jahr,1,1),Eintritt),O9>IF(Austritt="",DATE(Jahr,12,31),Austritt)),0,IF(OR(ISERROR(VLOOKUP(O9,Stammdaten!$I$9:$J$26,2,FALSE)),SUMIFS(Stammdaten!$J$9:$J$26,Stammdaten!$I$9:$I$26,O9)=0),VLOOKUP(TEXT(O9,"TTT"),Stammdaten!$B$20:$F$26,5,FALSE),0))) -> 0 | R9: =DATE(Jahr,MONTH(R$4),$B9) -> 45813 | S9: =IF($B9>DAY(EOMONTH(R$4,0)),"",SUMIFS(INDIRECT(TEXT(R9,"MMM")&"!$L$9:$L$999"),INDIRECT(TEXT(R9,"MMM")&"!$B$9:$B$999"),R9)+SUMIFS(Abwesenheit!$J$3:$J$199,Abwesenheit!$D$3:$D$199,R9)) -> 0 | T9: =IF($B9>DAY(EOMONTH(R$4,0)),"",IF(OR(R9<IF(YEAR(Eintritt)<Jahr,DATE(Jahr,1,1),Eintritt),R9>IF(Austritt="",DATE(Jahr,12,31),Austritt)),0,IF(OR(ISERROR(VLOOKUP(R9,Stammdaten!$I$9:$J$26,2,FALSE)),SUMIFS(Stammdaten!$J$9:$J$26,Stammdaten!$I$9:$I$26,R9)=0),VLOOKUP(TEXT(R9,"TTT"),Stammdaten!$B$20:$F$26,5,FALSE),0))) -> 0 | U9: =DATE(Jahr,MONTH(U$4),$B9) -> 45843 | V9: =IF($B9>DAY(EOMONTH(U$4,0)),"",SUMIFS(INDIRECT(TEXT(U9,"MMM")&"!$L$9:$L$999"),INDIRECT(TEXT(U9,"MMM")&"!$B$9:$B$999"),U9)+SUMIFS(Abwesenheit!$J$3:$J$199,Abwesenheit!$D$3:$D$199,U9)) -> 0 | W9: =IF($B9>DAY(EOMONTH(U$4,0)),"",IF(OR(U9<IF(YEAR(Eintritt)<Jahr,DATE(Jahr,1,1),Eintritt),U9>IF(Austritt="",DATE(Jahr,12,31),Austritt)),0,IF(OR(ISERROR(VLOOKUP(U9,Stammdaten!$I$9:$J$26,2,FALSE)),SUMIFS(Stammdaten!$J$9:$J$26,Stammdaten!$I$9:$I$26,U9)=0),VLOOKUP(TEXT(U9,"TTT"),Stammdaten!$B$20:$F$26,5,FALSE),0))) -> 0 | X9: =DATE(Jahr,MONTH(X$4),$B9) -> 45874 | Y9: =IF($B9>DAY(EOMONTH(X$4,0)),"",SUMIFS(INDIRECT(TEXT(X9,"MMM")&"!$L$9:$L$999"),INDIRECT(TEXT(X9,"MMM")&"!$B$9:$B$999"),X9)+SUMIFS(Abwesenheit!$J$3:$J$199,Abwesenheit!$D$3:$D$199,X9)) -> 0 | Z9: =IF($B9>DAY(EOMONTH(X$4,0)),"",IF(OR(X9<IF(YEAR(Eintritt)<Jahr,DATE(Jahr,1,1),Eintritt),X9>IF(Austritt="",DATE(Jahr,12,31),Austritt)),0,IF(OR(ISERROR(VLOOKUP(X9,Stammdaten!$I$9:$J$26,2,FALSE)),SUMIFS(Stammdaten!$J$9:$J$26,Stammdaten!$I$9:$I$26,X9)=0),VLOOKUP(TEXT(X9,"TTT"),Stammdaten!$B$20:$F$26,5,FALSE),0))) -> 0 | AA9: =DATE(Jahr,MONTH(AA$4),$B9) -> 45905 | AB9: =IF($B9>DAY(EOMONTH(AA$4,0)),"",SUMIFS(INDIRECT(TEXT(AA9,"MMM")&"!$L$9:$L$999"),INDIRECT(TEXT(AA9,"MMM")&"!$B$9:$B$999"),AA9)+SUMIFS(Abwesenheit!$J$3:$J$199,Abwesenheit!$D$3:$D$199,AA9)) -> 0 | AC9: =IF($B9>DAY(EOMONTH(AA$4,0)),"",IF(OR(AA9<IF(YEAR(Eintritt)<Jahr,DATE(Jahr,1,1),Eintritt),AA9>IF(Austritt="",DATE(Jahr,12,31),Austritt)),0,IF(OR(ISERROR(VLOOKUP(AA9,Stammdaten!$I$9:$J$26,2,FALSE)),SUMIFS(Stammdaten!$J$9:$J$26,Stammdaten!$I$9:$I$26,AA9)=0),VLOOKUP(TEXT(AA9,"TTT"),Stammdaten!$B$20:$F$26,5,FALSE),0))) -> 0 | AD9: =DATE(Jahr,MONTH(AD$4),$B9) -> 45935 | AE9: =IF($B9>DAY(EOMONTH(AD$4,0)),"",SUMIFS(INDIRECT(TEXT(AD9,"MMM")&"!$L$9:$L$999"),INDIRECT(TEXT(AD9,"MMM")&"!$B$9:$B$999"),AD9)+SUMIFS(Abwesenheit!$J$3:$J$199,Abwesenheit!$D$3:$D$199,AD9)) -> 0 | AF9: =IF($B9>DAY(EOMONTH(AD$4,0)),"",IF(OR(AD9<IF(YEAR(Eintritt)<Jahr,DATE(Jahr,1,1),Eintritt),AD9>IF(Austritt="",DATE(Jahr,12,31),Austritt)),0,IF(OR(ISERROR(VLOOKUP(AD9,Stammdaten!$I$9:$J$26,2,FALSE)),SUMIFS(Stammdaten!$J$9:$J$26,Stammdaten!$I$9:$I$26,AD9)=0),VLOOKUP(TEXT(AD9,"TTT"),Stammdaten!$B$20:$F$26,5,FALSE),0))) -> 0 | AG9: =DATE(Jahr,MONTH(AG$4),$B9) -> 45966 | AH9: =IF($B9>DAY(EOMONTH(AG$4,0)),"",SUMIFS(INDIRECT(TEXT(AG9,"MMM")&"!$L$9:$L$999"),INDIRECT(TEXT(AG9,"MMM")&"!$B$9:$B$999"),AG9)+SUMIFS(Abwesenheit!$J$3:$J$199,Abwesenheit!$D$3:$D$199,AG9)) -> 0 | AI9: =IF($B9>DAY(EOMONTH(AG$4,0)),"",IF(OR(AG9<IF(YEAR(Eintritt)<Jahr,DATE(Jahr,1,1),Eintritt),AG9>IF(Austritt="",DATE(Jahr,12,31),Austritt)),0,IF(OR(ISERROR(VLOOKUP(AG9,Stammdaten!$I$9:$J$26,2,FALSE)),SUMIFS(Stammdaten!$J$9:$J$26,Stammdaten!$I$9:$I$26,AG9)=0),VLOOKUP(TEXT(AG9,"TTT"),Stammdaten!$B$20:$F$26,5,FALSE),0))) -> 0 | AJ9: =DATE(Jahr,MONTH(AJ$4),$B9) -> 45996 | AK9: =IF($B9>DAY(EOMONTH(AJ$4,0)),"",SUMIFS(INDIRECT(TEXT(AJ9,"MMM")&"!$L$9:$L$999"),INDIRECT(TEXT(AJ9,"MMM")&"!$B$9:$B$999"),AJ9)+SUMIFS(Abwesenheit!$J$3:$J$199,Abwesenheit!$D$3:$D$199,AJ9)) -> 0 | AL9: =IF($B9>DAY(EOMONTH(AJ$4,0)),"",IF(OR(AJ9<IF(YEAR(Eintritt)<Jahr,DATE(Jahr,1,1),Eintritt),AJ9>IF(Austritt="",DATE(Jahr,12,31),Austritt)),0,VLOOKUP(TEXT(AJ9,"TTT"),Stammdaten!$B$20:$F$26,5,FALSE)-IF(ISERROR(VLOOKUP(AJ9,Stammdaten!$I$9:$J$26,2,FALSE)),0,SUMIFS(Stammdaten!$J$9:$J$26,Stammdaten!$I$9:$I$26,AJ9)/24))) -> 0 | AM9: 5
B10: 6 | C10: =DATE(Jahr,MONTH(C$4),$B10) -> 45663 | D10: =IF($B10>DAY(EOMONTH(C$4,0)),"",SUMIFS(INDIRECT(TEXT(C10,"MMM")&"!$L$9:$L$999"),INDIRECT(TEXT(C10,"MMM")&"!$B$9:$B$999"),C10)+SUMIFS(Abwesenheit!$J$3:$J$199,Abwesenheit!$D$3:$D$199,C10)) -> 0 | E10: =IF($B10>DAY(EOMONTH(C$4,0)),"",IF(OR(C10<IF(YEAR(Eintritt)<Jahr,DATE(Jahr,1,1),Eintritt),C10>IF(Austritt="",DATE(Jahr,12,31),Austritt)),0,IF(OR(ISERROR(VLOOKUP(C10,Stammdaten!$I$9:$J$26,2,FALSE)),SUMIFS(Stammdaten!$J$9:$J$26,Stammdaten!$I$9:$I$26,C10)=0),VLOOKUP(TEXT(C10,"TTT"),Stammdaten!$B$20:$F$26,5,FALSE),0))) -> 0 | F10: =DATE(Jahr,MONTH(F$4),$B10) -> 45694 | G10: =IF($B10>DAY(EOMONTH(F$4,0)),"",SUMIFS(INDIRECT(TEXT(F10,"MMM")&"!$L$9:$L$999"),INDIRECT(TEXT(F10,"MMM")&"!$B$9:$B$999"),F10)+SUMIFS(Abwesenheit!$J$3:$J$199,Abwesenheit!$D$3:$D$199,F10)) -> 0 | H10: =IF($B10>DAY(EOMONTH(F$4,0)),"",IF(OR(F10<IF(YEAR(Eintritt)<Jahr,DATE(Jahr,1,1),Eintritt),F10>IF(Austritt="",DATE(Jahr,12,31),Austritt)),0,IF(OR(ISERROR(VLOOKUP(F10,Stammdaten!$I$9:$J$26,2,FALSE)),SUMIFS(Stammdaten!$J$9:$J$26,Stammdaten!$I$9:$I$26,F10)=0),VLOOKUP(TEXT(F10,"TTT"),Stammdaten!$B$20:$F$26,5,FALSE),0))) -> 0 | I10: =DATE(Jahr,MONTH(I$4),$B10) -> 45722 | J10: =IF($B10>DAY(EOMONTH(I$4,0)),"",SUMIFS(INDIRECT(TEXT(I10,"MMM")&"!$L$9:$L$999"),INDIRECT(TEXT(I10,"MMM")&"!$B$9:$B$999"),I10)+SUMIFS(Abwesenheit!$J$3:$J$199,Abwesenheit!$D$3:$D$199,I10)) -> 0 | K10: =IF($B10>DAY(EOMONTH(I$4,0)),"",IF(OR(I10<IF(YEAR(Eintritt)<Jahr,DATE(Jahr,1,1),Eintritt),I10>IF(Austritt="",DATE(Jahr,12,31),Austritt)),0,IF(OR(ISERROR(VLOOKUP(I10,Stammdaten!$I$9:$J$26,2,FALSE)),SUMIFS(Stammdaten!$J$9:$J$26,Stammdaten!$I$9:$I$26,I10)=0),VLOOKUP(TEXT(I10,"TTT"),Stammdaten!$B$20:$F$26,5,FALSE),0))) -> 0 | L10: =DATE(Jahr,MONTH(L$4),$B10) -> 45753 | M10: =IF($B10>DAY(EOMONTH(L$4,0)),"",SUMIFS(INDIRECT(TEXT(L10,"MMM")&"!$L$9:$L$999"),INDIRECT(TEXT(L10,"MMM")&"!$B$9:$B$999"),L10)+SUMIFS(Abwesenheit!$J$3:$J$199,Abwesenheit!$D$3:$D$199,L10)) -> 0 | N10: =IF($B10>DAY(EOMONTH(L$4,0)),"",IF(OR(L10<IF(YEAR(Eintritt)<Jahr,DATE(Jahr,1,1),Eintritt),L10>IF(Austritt="",DATE(Jahr,12,31),Austritt)),0,IF(OR(ISERROR(VLOOKUP(L10,Stammdaten!$I$9:$J$26,2,FALSE)),SUMIFS(Stammdaten!$J$9:$J$26,Stammdaten!$I$9:$I$26,L10)=0),VLOOKUP(TEXT(L10,"TTT"),Stammdaten!$B$20:$F$26,5,FALSE),0))) -> 0 | O10: =DATE(Jahr,MONTH(O$4),$B10) -> 45783 | P10: =IF($B10>DAY(EOMONTH(O$4,0)),"",SUMIFS(INDIRECT(TEXT(O10,"MMM")&"!$L$9:$L$999"),INDIRECT(TEXT(O10,"MMM")&"!$B$9:$B$999"),O10)+SUMIFS(Abwesenheit!$J$3:$J$199,Abwesenheit!$D$3:$D$199,O10)) -> 0 | Q10: =IF($B10>DAY(EOMONTH(O$4,0)),"",IF(OR(O10<IF(YEAR(Eintritt)<Jahr,DATE(Jahr,1,1),Eintritt),O10>IF(Austritt="",DATE(Jahr,12,31),Austritt)),0,IF(OR(ISERROR(VLOOKUP(O10,Stammdaten!$I$9:$J$26,2,FALSE)),SUMIFS(Stammdaten!$J$9:$J$26,Stammdaten!$I$9:$I$26,O10)=0),VLOOKUP(TEXT(O10,"TTT"),Stammdaten!$B$20:$F$26,5,FALSE),0))) -> 0 | R10: =DATE(Jahr,MONTH(R$4),$B10) -> 45814 | S10: =IF($B10>DAY(EOMONTH(R$4,0)),"",SUMIFS(INDIRECT(TEXT(R10,"MMM")&"!$L$9:$L$999"),INDIRECT(TEXT(R10,"MMM")&"!$B$9:$B$999"),R10)+SUMIFS(Abwesenheit!$J$3:$J$199,Abwesenheit!$D$3:$D$199,R10)) -> 0 | T10: =IF($B10>DAY(EOMONTH(R$4,0)),"",IF(OR(R10<IF(YEAR(Eintritt)<Jahr,DATE(Jahr,1,1),Eintritt),R10>IF(Austritt="",DATE(Jahr,12,31),Austritt)),0,IF(OR(ISERROR(VLOOKUP(R10,Stammdaten!$I$9:$J$26,2,FALSE)),SUMIFS(Stammdaten!$J$9:$J$26,Stammdaten!$I$9:$I$26,R10)=0),VLOOKUP(TEXT(R10,"TTT"),Stammdaten!$B$20:$F$26,5,FALSE),0))) -> 0 | U10: =DATE(Jahr,MONTH(U$4),$B10) -> 45844 | V10: =IF($B10>DAY(EOMONTH(U$4,0)),"",SUMIFS(INDIRECT(TEXT(U10,"MMM")&"!$L$9:$L$999"),INDIRECT(TEXT(U10,"MMM")&"!$B$9:$B$999"),U10)+SUMIFS(Abwesenheit!$J$3:$J$199,Abwesenheit!$D$3:$D$199,U10)) -> 0 | W10: =IF($B10>DAY(EOMONTH(U$4,0)),"",IF(OR(U10<IF(YEAR(Eintritt)<Jahr,DATE(Jahr,1,1),Eintritt),U10>IF(Austritt="",DATE(Jahr,12,31),Austritt)),0,IF(OR(ISERROR(VLOOKUP(U10,Stammdaten!$I$9:$J$26,2,FALSE)),SUMIFS(Stammdaten!$J$9:$J$26,Stammdaten!$I$9:$I$26,U10)=0),VLOOKUP(TEXT(U10,"TTT"),Stammdaten!$B$20:$F$26,5,FALSE),0))) -> 0 | X10: =DATE(Jahr,MONTH(X$4),$B10) -> 45875 | Y10: =IF($B10>DAY(EOMONTH(X$4,0)),"",SUMIFS(INDIRECT(TEXT(X10,"MMM")&"!$L$9:$L$999"),INDIRECT(TEXT(X10,"MMM")&"!$B$9:$B$999"),X10)+SUMIFS(Abwesenheit!$J$3:$J$199,Abwesenheit!$D$3:$D$199,X10)) -> 0 | Z10: =IF($B10>DAY(EOMONTH(X$4,0)),"",IF(OR(X10<IF(YEAR(Eintritt)<Jahr,DATE(Jahr,1,1),Eintritt),X10>IF(Austritt="",DATE(Jahr,12,31),Austritt)),0,IF(OR(ISERROR(VLOOKUP(X10,Stammdaten!$I$9:$J$26,2,FALSE)),SUMIFS(Stammdaten!$J$9:$J$26,Stammdaten!$I$9:$I$26,X10)=0),VLOOKUP(TEXT(X10,"TTT"),Stammdaten!$B$20:$F$26,5,FALSE),0))) -> 0 | AA10: =DATE(Jahr,MONTH(AA$4),$B10) -> 45906 | AB10: =IF($B10>DAY(EOMONTH(AA$4,0)),"",SUMIFS(INDIRECT(TEXT(AA10,"MMM")&"!$L$9:$L$999"),INDIRECT(TEXT(AA10,"MMM")&"!$B$9:$B$999"),AA10)+SUMIFS(Abwesenheit!$J$3:$J$199,Abwesenheit!$D$3:$D$199,AA10)) -> 0 | AC10: =IF($B10>DAY(EOMONTH(AA$4,0)),"",IF(OR(AA10<IF(YEAR(Eintritt)<Jahr,DATE(Jahr,1,1),Eintritt),AA10>IF(Austritt="",DATE(Jahr,12,31),Austritt)),0,IF(OR(ISERROR(VLOOKUP(AA10,Stammdaten!$I$9:$J$26,2,FALSE)),SUMIFS(Stammdaten!$J$9:$J$26,Stammdaten!$I$9:$I$26,AA10)=0),VLOOKUP(TEXT(AA10,"TTT"),Stammdaten!$B$20:$F$26,5,FALSE),0))) -> 0 | AD10: =DATE(Jahr,MONTH(AD$4),$B10) -> 45936 | AE10: =IF($B10>DAY(EOMONTH(AD$4,0)),"",SUMIFS(INDIRECT(TEXT(AD10,"MMM")&"!$L$9:$L$999"),INDIRECT(TEXT(AD10,"MMM")&"!$B$9:$B$999"),AD10)+SUMIFS(Abwesenheit!$J$3:$J$199,Abwesenheit!$D$3:$D$199,AD10)) -> 0 | AF10: =IF($B10>DAY(EOMONTH(AD$4,0)),"",IF(OR(AD10<IF(YEAR(Eintritt)<Jahr,DATE(Jahr,1,1),Eintritt),AD10>IF(Austritt="",DATE(Jahr,12,31),Austritt)),0,IF(OR(ISERROR(VLOOKUP(AD10,Stammdaten!$I$9:$J$26,2,FALSE)),SUMIFS(Stammdaten!$J$9:$J$26,Stammdaten!$I$9:$I$26,AD10)=0),VLOOKUP(TEXT(AD10,"TTT"),Stammdaten!$B$20:$F$26,5,FALSE),0))) -> 0 | AG10: =DATE(Jahr,MONTH(AG$4),$B10) -> 45967 | AH10: =IF($B10>DAY(EOMONTH(AG$4,0)),"",SUMIFS(INDIRECT(TEXT(AG10,"MMM")&"!$L$9:$L$999"),INDIRECT(TEXT(AG10,"MMM")&"!$B$9:$B$999"),AG10)+SUMIFS(Abwesenheit!$J$3:$J$199,Abwesenheit!$D$3:$D$199,AG10)) -> 0 | AI10: =IF($B10>DAY(EOMONTH(AG$4,0)),"",IF(OR(AG10<IF(YEAR(Eintritt)<Jahr,DATE(Jahr,1,1),Eintritt),AG10>IF(Austritt="",DATE(Jahr,12,31),Austritt)),0,IF(OR(ISERROR(VLOOKUP(AG10,Stammdaten!$I$9:$J$26,2,FALSE)),SUMIFS(Stammdaten!$J$9:$J$26,Stammdaten!$I$9:$I$26,AG10)=0),VLOOKUP(TEXT(AG10,"TTT"),Stammdaten!$B$20:$F$26,5,FALSE),0))) -> 0 | AJ10: =DATE(Jahr,MONTH(AJ$4),$B10) -> 45997 | AK10: =IF($B10>DAY(EOMONTH(AJ$4,0)),"",SUMIFS(INDIRECT(TEXT(AJ10,"MMM")&"!$L$9:$L$999"),INDIRECT(TEXT(AJ10,"MMM")&"!$B$9:$B$999"),AJ10)+SUMIFS(Abwesenheit!$J$3:$J$199,Abwesenheit!$D$3:$D$199,AJ10)) -> 0 | AL10: =IF($B10>DAY(EOMONTH(AJ$4,0)),"",IF(OR(AJ10<IF(YEAR(Eintritt)<Jahr,DATE(Jahr,1,1),Eintritt),AJ10>IF(Austritt="",DATE(Jahr,12,31),Austritt)),0,VLOOKUP(TEXT(AJ10,"TTT"),Stammdaten!$B$20:$F$26,5,FALSE)-IF(ISERROR(VLOOKUP(AJ10,Stammdaten!$I$9:$J$26,2,FALSE)),0,SUMIFS(Stammdaten!$J$9:$J$26,Stammdaten!$I$9:$I$26,AJ10)/24))) -> 0 | AM10: 6
B11: 7 | C11: =DATE(Jahr,MONTH(C$4),$B11) -> 45664 | D11: =IF($B11>DAY(EOMONTH(C$4,0)),"",SUMIFS(INDIRECT(TEXT(C11,"MMM")&"!$L$9:$L$999"),INDIRECT(TEXT(C11,"MMM")&"!$B$9:$B$999"),C11)+SUMIFS(Abwesenheit!$J$3:$J$199,Abwesenheit!$D$3:$D$199,C11)) -> 0 | E11: =IF($B11>DAY(EOMONTH(C$4,0)),"",IF(OR(C11<IF(YEAR(Eintritt)<Jahr,DATE(Jahr,1,1),Eintritt),C11>IF(Austritt="",DATE(Jahr,12,31),Austritt)),0,IF(OR(ISERROR(VLOOKUP(C11,Stammdaten!$I$9:$J$26,2,FALSE)),SUMIFS(Stammdaten!$J$9:$J$26,Stammdaten!$I$9:$I$26,C11)=0),VLOOKUP(TEXT(C11,"TTT"),Stammdaten!$B$20:$F$26,5,FALSE),0))) -> 0 | F11: =DATE(Jahr,MONTH(F$4),$B11) -> 45695 | G11: =IF($B11>DAY(EOMONTH(F$4,0)),"",SUMIFS(INDIRECT(TEXT(F11,"MMM")&"!$L$9:$L$999"),INDIRECT(TEXT(F11,"MMM")&"!$B$9:$B$999"),F11)+SUMIFS(Abwesenheit!$J$3:$J$199,Abwesenheit!$D$3:$D$199,F11)) -> 0 | H11: =IF($B11>DAY(EOMONTH(F$4,0)),"",IF(OR(F11<IF(YEAR(Eintritt)<Jahr,DATE(Jahr,1,1),Eintritt),F11>IF(Austritt="",DATE(Jahr,12,31),Austritt)),0,IF(OR(ISERROR(VLOOKUP(F11,Stammdaten!$I$9:$J$26,2,FALSE)),SUMIFS(Stammdaten!$J$9:$J$26,Stammdaten!$I$9:$I$26,F11)=0),VLOOKUP(TEXT(F11,"TTT"),Stammdaten!$B$20:$F$26,5,FALSE),0))) -> 0 | I11: =DATE(Jahr,MONTH(I$4),$B11) -> 45723 | J11: =IF($B11>DAY(EOMONTH(I$4,0)),"",SUMIFS(INDIRECT(TEXT(I11,"MMM")&"!$L$9:$L$999"),INDIRECT(TEXT(I11,"MMM")&"!$B$9:$B$999"),I11)+SUMIFS(Abwesenheit!$J$3:$J$199,Abwesenheit!$D$3:$D$199,I11)) -> 0 | K11: =IF($B11>DAY(EOMONTH(I$4,0)),"",IF(OR(I11<IF(YEAR(Eintritt)<Jahr,DATE(Jahr,1,1),Eintritt),I11>IF(Austritt="",DATE(Jahr,12,31),Austritt)),0,IF(OR(ISERROR(VLOOKUP(I11,Stammdaten!$I$9:$J$26,2,FALSE)),SUMIFS(Stammdaten!$J$9:$J$26,Stammdaten!$I$9:$I$26,I11)=0),VLOOKUP(TEXT(I11,"TTT"),Stammdaten!$B$20:$F$26,5,FALSE),0))) -> 0 | L11: =DATE(Jahr,MONTH(L$4),$B11) -> 45754 | M11: =IF($B11>DAY(EOMONTH(L$4,0)),"",SUMIFS(INDIRECT(TEXT(L11,"MMM")&"!$L$9:$L$999"),INDIRECT(TEXT(L11,"MMM")&"!$B$9:$B$999"),L11)+SUMIFS(Abwesenheit!$J$3:$J$199,Abwesenheit!$D$3:$D$199,L11)) -> 0 | N11: =IF($B11>DAY(EOMONTH(L$4,0)),"",IF(OR(L11<IF(YEAR(Eintritt)<Jahr,DATE(Jahr,1,1),Eintritt),L11>IF(Austritt="",DATE(Jahr,12,31),Austritt)),0,IF(OR(ISERROR(VLOOKUP(L11,Stammdaten!$I$9:$J$26,2,FALSE)),SUMIFS(Stammdaten!$J$9:$J$26,Stammdaten!$I$9:$I$26,L11)=0),VLOOKUP(TEXT(L11,"TTT"),Stammdaten!$B$20:$F$26,5,FALSE),0))) -> 0 | O11: =DATE(Jahr,MONTH(O$4),$B11) -> 45784 | P11: =IF($B11>DAY(EOMONTH(O$4,0)),"",SUMIFS(INDIRECT(TEXT(O11,"MMM")&"!$L$9:$L$999"),INDIRECT(TEXT(O11,"MMM")&"!$B$9:$B$999"),O11)+SUMIFS(Abwesenheit!$J$3:$J$199,Abwesenheit!$D$3:$D$199,O11)) -> 0 | Q11: =IF($B11>DAY(EOMONTH(O$4,0)),"",IF(OR(O11<IF(YEAR(Eintritt)<Jahr,DATE(Jahr,1,1),Eintritt),O11>IF(Austritt="",DATE(Jahr,12,31),Austritt)),0,IF(OR(ISERROR(VLOOKUP(O11,Stammdaten!$I$9:$J$26,2,FALSE)),SUMIFS(Stammdaten!$J$9:$J$26,Stammdaten!$I$9:$I$26,O11)=0),VLOOKUP(TEXT(O11,"TTT"),Stammdaten!$B$20:$F$26,5,FALSE),0))) -> 0 | R11: =DATE(Jahr,MONTH(R$4),$B11) -> 45815 | S11: =IF($B11>DAY(EOMONTH(R$4,0)),"",SUMIFS(INDIRECT(TEXT(R11,"MMM")&"!$L$9:$L$999"),INDIRECT(TEXT(R11,"MMM")&"!$B$9:$B$999"),R11)+SUMIFS(Abwesenheit!$J$3:$J$199,Abwesenheit!$D$3:$D$199,R11)) -> 0 | T11: =IF($B11>DAY(EOMONTH(R$4,0)),"",IF(OR(R11<IF(YEAR(Eintritt)<Jahr,DATE(Jahr,1,1),Eintritt),R11>IF(Austritt="",DATE(Jahr,12,31),Austritt)),0,IF(OR(ISERROR(VLOOKUP(R11,Stammdaten!$I$9:$J$26,2,FALSE)),SUMIFS(Stammdaten!$J$9:$J$26,Stammdaten!$I$9:$I$26,R11)=0),VLOOKUP(TEXT(R11,"TTT"),Stammdaten!$B$20:$F$26,5,FALSE),0))) -> 0 | U11: =DATE(Jahr,MONTH(U$4),$B11) -> 45845 | V11: =IF($B11>DAY(EOMONTH(U$4,0)),"",SUMIFS(INDIRECT(TEXT(U11,"MMM")&"!$L$9:$L$999"),INDIRECT(TEXT(U11,"MMM")&"!$B$9:$B$999"),U11)+SUMIFS(Abwesenheit!$J$3:$J$199,Abwesenheit!$D$3:$D$199,U11)) -> 0.33333333 | W11: =IF($B11>DAY(EOMONTH(U$4,0)),"",IF(OR(U11<IF(YEAR(Eintritt)<Jahr,DATE(Jahr,1,1),Eintritt),U11>IF(Austritt="",DATE(Jahr,12,31),Austritt)),0,IF(OR(ISERROR(VLOOKUP(U11,Stammdaten!$I$9:$J$26,2,FALSE)),SUMIFS(Stammdaten!$J$9:$J$26,Stammdaten!$I$9:$I$26,U11)=0),VLOOKUP(TEXT(U11,"TTT"),Stammdaten!$B$20:$F$26,5,FALSE),0))) -> 0.33333333 | X11: =DATE(Jahr,MONTH(X$4),$B11) -> 45876 | Y11: =IF($B11>DAY(EOMONTH(X$4,0)),"",SUMIFS(INDIRECT(TEXT(X11,"MMM")&"!$L$9:$L$999"),INDIRECT(TEXT(X11,"MMM")&"!$B$9:$B$999"),X11)+SUMIFS(Abwesenheit!$J$3:$J$199,Abwesenheit!$D$3:$D$199,X11)) -> 0 | Z11: =IF($B11>DAY(EOMONTH(X$4,0)),"",IF(OR(X11<IF(YEAR(Eintritt)<Jahr,DATE(Jahr,1,1),Eintritt),X11>IF(Austritt="",DATE(Jahr,12,31),Austritt)),0,IF(OR(ISERROR(VLOOKUP(X11,Stammdaten!$I$9:$J$26,2,FALSE)),SUMIFS(Stammdaten!$J$9:$J$26,Stammdaten!$I$9:$I$26,X11)=0),VLOOKUP(TEXT(X11,"TTT"),Stammdaten!$B$20:$F$26,5,FALSE),0))) -> 0 | AA11: =DATE(Jahr,MONTH(AA$4),$B11) -> 45907 | AB11: =IF($B11>DAY(EOMONTH(AA$4,0)),"",SUMIFS(INDIRECT(TEXT(AA11,"MMM")&"!$L$9:$L$999"),INDIRECT(TEXT(AA11,"MMM")&"!$B$9:$B$999"),AA11)+SUMIFS(Abwesenheit!$J$3:$J$199,Abwesenheit!$D$3:$D$199,AA11)) -> 0 | AC11: =IF($B11>DAY(EOMONTH(AA$4,0)),"",IF(OR(AA11<IF(YEAR(Eintritt)<Jahr,DATE(Jahr,1,1),Eintritt),AA11>IF(Austritt="",DATE(Jahr,12,31),Austritt)),0,IF(OR(ISERROR(VLOOKUP(AA11,Stammdaten!$I$9:$J$26,2,FALSE)),SUMIFS(Stammdaten!$J$9:$J$26,Stammdaten!$I$9:$I$26,AA11)=0),VLOOKUP(TEXT(AA11,"TTT"),Stammdaten!$B$20:$F$26,5,FALSE),0))) -> 0 | AD11: =DATE(Jahr,MONTH(AD$4),$B11) -> 45937 | AE11: =IF($B11>DAY(EOMONTH(AD$4,0)),"",SUMIFS(INDIRECT(TEXT(AD11,"MMM")&"!$L$9:$L$999"),INDIRECT(TEXT(AD11,"MMM")&"!$B$9:$B$999"),AD11)+SUMIFS(Abwesenheit!$J$3:$J$199,Abwesenheit!$D$3:$D$199,AD11)) -> 0 | AF11: =IF($B11>DAY(EOMONTH(AD$4,0)),"",IF(OR(AD11<IF(YEAR(Eintritt)<Jahr,DATE(Jahr,1,1),Eintritt),AD11>IF(Austritt="",DATE(Jahr,12,31),Austritt)),0,IF(OR(ISERROR(VLOOKUP(AD11,Stammdaten!$I$9:$J$26,2,FALSE)),SUMIFS(Stammdaten!$J$9:$J$26,Stammdaten!$I$9:$I$26,AD11)=0),VLOOKUP(TEXT(AD11,"TTT"),Stammdaten!$B$20:$F$26,5,FALSE),0))) -> 0 | AG11: =DATE(Jahr,MONTH(AG$4),$B11) -> 45968 | AH11: =IF($B11>DAY(EOMONTH(AG$4,0)),"",SUMIFS(INDIRECT(TEXT(AG11,"MMM")&"!$L$9:$L$999"),INDIRECT(TEXT(AG11,"MMM")&"!$B$9:$B$999"),AG11)+SUMIFS(Abwesenheit!$J$3:$J$199,Abwesenheit!$D$3:$D$199,AG11)) -> 0 | AI11: =IF($B11>DAY(EOMONTH(AG$4,0)),"",IF(OR(AG11<IF(YEAR(Eintritt)<Jahr,DATE(Jahr,1,1),Eintritt),AG11>IF(Austritt="",DATE(Jahr,12,31),Austritt)),0,IF(OR(ISERROR(VLOOKUP(AG11,Stammdaten!$I$9:$J$26,2,FALSE)),SUMIFS(Stammdaten!$J$9:$J$26,Stammdaten!$I$9:$I$26,AG11)=0),VLOOKUP(TEXT(AG11,"TTT"),Stammdaten!$B$20:$F$26,5,FALSE),0))) -> 0 | AJ11: =DATE(Jahr,MONTH(AJ$4),$B11) -> 45998 | AK11: =IF($B11>DAY(EOMONTH(AJ$4,0)),"",SUMIFS(INDIRECT(TEXT(AJ11,"MMM")&"!$L$9:$L$999"),INDIRECT(TEXT(AJ11,"MMM")&"!$B$9:$B$999"),AJ11)+SUMIFS(Abwesenheit!$J$3:$J$199,Abwesenheit!$D$3:$D$199,AJ11)) -> 0 | AL11: =IF($B11>DAY(EOMONTH(AJ$4,0)),"",IF(OR(AJ11<IF(YEAR(Eintritt)<Jahr,DATE(Jahr,1,1),Eintritt),AJ11>IF(Austritt="",DATE(Jahr,12,31),Austritt)),0,VLOOKUP(TEXT(AJ11,"TTT"),Stammdaten!$B$20:$F$26,5,FALSE)-IF(ISERROR(VLOOKUP(AJ11,Stammdaten!$I$9:$J$26,2,FALSE)),0,SUMIFS(Stammdaten!$J$9:$J$26,Stammdaten!$I$9:$I$26,AJ11)/24))) -> 0 | AM11: 7
B12: 8 | C12: =DATE(Jahr,MONTH(C$4),$B12) -> 45665 | D12: =IF($B12>DAY(EOMONTH(C$4,0)),"",SUMIFS(INDIRECT(TEXT(C12,"MMM")&"!$L$9:$L$999"),INDIRECT(TEXT(C12,"MMM")&"!$B$9:$B$999"),C12)+SUMIFS(Abwesenheit!$J$3:$J$199,Abwesenheit!$D$3:$D$199,C12)) -> 0 | E12: =IF($B12>DAY(EOMONTH(C$4,0)),"",IF(OR(C12<IF(YEAR(Eintritt)<Jahr,DATE(Jahr,1,1),Eintritt),C12>IF(Austritt="",DATE(Jahr,12,31),Austritt)),0,IF(OR(ISERROR(VLOOKUP(C12,Stammdaten!$I$9:$J$26,2,FALSE)),SUMIFS(Stammdaten!$J$9:$J$26,Stammdaten!$I$9:$I$26,C12)=0),VLOOKUP(TEXT(C12,"TTT"),Stammdaten!$B$20:$F$26,5,FALSE),0))) -> 0 | F12: =DATE(Jahr,MONTH(F$4),$B12) -> 45696 | G12: =IF($B12>DAY(EOMONTH(F$4,0)),"",SUMIFS(INDIRECT(TEXT(F12,"MMM")&"!$L$9:$L$999"),INDIRECT(TEXT(F12,"MMM")&"!$B$9:$B$999"),F12)+SUMIFS(Abwesenheit!$J$3:$J$199,Abwesenheit!$D$3:$D$199,F12)) -> 0 | H12: =IF($B12>DAY(EOMONTH(F$4,0)),"",IF(OR(F12<IF(YEAR(Eintritt)<Jahr,DATE(Jahr,1,1),Eintritt),F12>IF(Austritt="",DATE(Jahr,12,31),Austritt)),0,IF(OR(ISERROR(VLOOKUP(F12,Stammdaten!$I$9:$J$26,2,FALSE)),SUMIFS(Stammdaten!$J$9:$J$26,Stammdaten!$I$9:$I$26,F12)=0),VLOOKUP(TEXT(F12,"TTT"),Stammdaten!$B$20:$F$26,5,FALSE),0))) -> 0 | I12: =DATE(Jahr,MONTH(I$4),$B12) -> 45724 | J12: =IF($B12>DAY(EOMONTH(I$4,0)),"",SUMIFS(INDIRECT(TEXT(I12,"MMM")&"!$L$9:$L$999"),INDIRECT(TEXT(I12,"MMM")&"!$B$9:$B$999"),I12)+SUMIFS(Abwesenheit!$J$3:$J$199,Abwesenheit!$D$3:$D$199,I12)) -> 0 | K12: =IF($B12>DAY(EOMONTH(I$4,0)),"",IF(OR(I12<IF(YEAR(Eintritt)<Jahr,DATE(Jahr,1,1),Eintritt),I12>IF(Austritt="",DATE(Jahr,12,31),Austritt)),0,IF(OR(ISERROR(VLOOKUP(I12,Stammdaten!$I$9:$J$26,2,FALSE)),SUMIFS(Stammdaten!$J$9:$J$26,Stammdaten!$I$9:$I$26,I12)=0),VLOOKUP(TEXT(I12,"TTT"),Stammdaten!$B$20:$F$26,5,FALSE),0))) -> 0 | L12: =DATE(Jahr,MONTH(L$4),$B12) -> 45755 | M12: =IF($B12>DAY(EOMONTH(L$4,0)),"",SUMIFS(INDIRECT(TEXT(L12,"MMM")&"!$L$9:$L$999"),INDIRECT(TEXT(L12,"MMM")&"!$B$9:$B$999"),L12)+SUMIFS(Abwesenheit!$J$3:$J$199,Abwesenheit!$D$3:$D$199,L12)) -> 0 | N12: =IF($B12>DAY(EOMONTH(L$4,0)),"",IF(OR(L12<IF(YEAR(Eintritt)<Jahr,DATE(Jahr,1,1),Eintritt),L12>IF(Austritt="",DATE(Jahr,12,31),Austritt)),0,IF(OR(ISERROR(VLOOKUP(L12,Stammdaten!$I$9:$J$26,2,FALSE)),SUMIFS(Stammdaten!$J$9:$J$26,Stammdaten!$I$9:$I$26,L12)=0),VLOOKUP(TEXT(L12,"TTT"),Stammdaten!$B$20:$F$26,5,FALSE),0))) -> 0 | O12: =DATE(Jahr,MONTH(O$4),$B12) -> 45785 | P12: =IF($B12>DAY(EOMONTH(O$4,0)),"",SUMIFS(INDIRECT(TEXT(O12,"MMM")&"!$L$9:$L$999"),INDIRECT(TEXT(O12,"MMM")&"!$B$9:$B$999"),O12)+SUMIFS(Abwesenheit!$J$3:$J$199,Abwesenheit!$D$3:$D$199,O12)) -> 0 | Q12: =IF($B12>DAY(EOMONTH(O$4,0)),"",IF(OR(O12<IF(YEAR(Eintritt)<Jahr,DATE(Jahr,1,1),Eintritt),O12>IF(Austritt="",DATE(Jahr,12,31),Austritt)),0,IF(OR(ISERROR(VLOOKUP(O12,Stammdaten!$I$9:$J$26,2,FALSE)),SUMIFS(Stammdaten!$J$9:$J$26,Stammdaten!$I$9:$I$26,O12)=0),VLOOKUP(TEXT(O12,"TTT"),Stammdaten!$B$20:$F$26,5,FALSE),0))) -> 0 | R12: =DATE(Jahr,MONTH(R$4),$B12) -> 45816 | S12: =IF($B12>DAY(EOMONTH(R$4,0)),"",SUMIFS(INDIRECT(TEXT(R12,"MMM")&"!$L$9:$L$999"),INDIRECT(TEXT(R12,"MMM")&"!$B$9:$B$999"),R12)+SUMIFS(Abwesenheit!$J$3:$J$199,Abwesenheit!$D$3:$D$199,R12)) -> 0 | T12: =IF($B12>DAY(EOMONTH(R$4,0)),"",IF(OR(R12<IF(YEAR(Eintritt)<Jahr,DATE(Jahr,1,1),Eintritt),R12>IF(Austritt="",DATE(Jahr,12,31),Austritt)),0,IF(OR(ISERROR(VLOOKUP(R12,Stammdaten!$I$9:$J$26,2,FALSE)),SUMIFS(Stammdaten!$J$9:$J$26,Stammdaten!$I$9:$I$26,R12)=0),VLOOKUP(TEXT(R12,"TTT"),Stammdaten!$B$20:$F$26,5,FALSE),0))) -> 0 | U12: =DATE(Jahr,MONTH(U$4),$B12) -> 45846 | V12: =IF($B12>DAY(EOMONTH(U$4,0)),"",SUMIFS(INDIRECT(TEXT(U12,"MMM")&"!$L$9:$L$999"),INDIRECT(TEXT(U12,"MMM")&"!$B$9:$B$999"),U12)+SUMIFS(Abwesenheit!$J$3:$J$199,Abwesenheit!$D$3:$D$199,U12)) -> 0.375 | W12: =IF($B12>DAY(EOMONTH(U$4,0)),"",IF(OR(U12<IF(YEAR(Eintritt)<Jahr,DATE(Jahr,1,1),Eintritt),U12>IF(Austritt="",DATE(Jahr,12,31),Austritt)),0,IF(OR(ISERROR(VLOOKUP(U12,Stammdaten!$I$9:$J$26,2,FALSE)),SUMIFS(Stammdaten!$J$9:$J$26,Stammdaten!$I$9:$I$26,U12)=0),VLOOKUP(TEXT(U12,"TTT"),Stammdaten!$B$20:$F$26,5,FALSE),0))) -> 0.33333333 | X12: =DATE(Jahr,MONTH(X$4),$B12) -> 45877 | Y12: =IF($B12>DAY(EOMONTH(X$4,0)),"",SUMIFS(INDIRECT(TEXT(X12,"MMM")&"!$L$9:$L$999"),INDIRECT(TEXT(X12,"MMM")&"!$B$9:$B$999"),X12)+SUMIFS(Abwesenheit!$J$3:$J$199,Abwesenheit!$D$3:$D$199,X12)) -> 0 | Z12: =IF($B12>DAY(EOMONTH(X$4,0)),"",IF(OR(X12<IF(YEAR(Eintritt)<Jahr,DATE(Jahr,1,1),Eintritt),X12>IF(Austritt="",DATE(Jahr,12,31),Austritt)),0,IF(OR(ISERROR(VLOOKUP(X12,Stammdaten!$I$9:$J$26,2,FALSE)),SUMIFS(Stammdaten!$J$9:$J$26,Stammdaten!$I$9:$I$26,X12)=0),VLOOKUP(TEXT(X12,"TTT"),Stammdaten!$B$20:$F$26,5,FALSE),0))) -> 0 | AA12: =DATE(Jahr,MONTH(AA$4),$B12) -> 45908 | AB12: =IF($B12>DAY(EOMONTH(AA$4,0)),"",SUMIFS(INDIRECT(TEXT(AA12,"MMM")&"!$L$9:$L$999"),INDIRECT(TEXT(AA12,"MMM")&"!$B$9:$B$999"),AA12)+SUMIFS(Abwesenheit!$J$3:$J$199,Abwesenheit!$D$3:$D$199,AA12)) -> 0 | AC12: =IF($B12>DAY(EOMONTH(AA$4,0)),"",IF(OR(AA12<IF(YEAR(Eintritt)<Jahr,DATE(Jahr,1,1),Eintritt),AA12>IF(Austritt="",DATE(Jahr,12,31),Austritt)),0,IF(OR(ISERROR(VLOOKUP(AA12,Stammdaten!$I$9:$J$26,2,FALSE)),SUMIFS(Stammdaten!$J$9:$J$26,Stammdaten!$I$9:$I$26,AA12)=0),VLOOKUP(TEXT(AA12,"TTT"),Stammdaten!$B$20:$F$26,5,FALSE),0))) -> 0 | AD12: =DATE(Jahr,MONTH(AD$4),$B12) -> 45938 | AE12: =IF($B12>DAY(EOMONTH(AD$4,0)),"",SUMIFS(INDIRECT(TEXT(AD12,"MMM")&"!$L$9:$L$999"),INDIRECT(TEXT(AD12,"MMM")&"!$B$9:$B$999"),AD12)+SUMIFS(Abwesenheit!$J$3:$J$199,Abwesenheit!$D$3:$D$199,AD12)) -> 0 | AF12: =IF($B12>DAY(EOMONTH(AD$4,0)),"",IF(OR(AD12<IF(YEAR(Eintritt)<Jahr,DATE(Jahr,1,1),Eintritt),AD12>IF(Austritt="",DATE(Jahr,12,31),Austritt)),0,IF(OR(ISERROR(VLOOKUP(AD12,Stammdaten!$I$9:$J$26,2,FALSE)),SUMIFS(Stammdaten!$J$9:$J$26,Stammdaten!$I$9:$I$26,AD12)=0),VLOOKUP(TEXT(AD12,"TTT"),Stammdaten!$B$20:$F$26,5,FALSE),0))) -> 0 | AG12: =DATE(Jahr,MONTH(AG$4),$B12) -> 45969 | AH12: =IF($B12>DAY(EOMONTH(AG$4,0)),"",SUMIFS(INDIRECT(TEXT(AG12,"MMM")&"!$L$9:$L$999"),INDIRECT(TEXT(AG12,"MMM")&"!$B$9:$B$999"),AG12)+SUMIFS(Abwesenheit!$J$3:$J$199,Abwesenheit!$D$3:$D$199,AG12)) -> 0 | AI12: =IF($B12>DAY(EOMONTH(AG$4,0)),"",IF(OR(AG12<IF(YEAR(Eintritt)<Jahr,DATE(Jahr,1,1),Eintritt),AG12>IF(Austritt="",DATE(Jahr,12,31),Austritt)),0,IF(OR(ISERROR(VLOOKUP(AG12,Stammdaten!$I$9:$J$26,2,FALSE)),SUMIFS(Stammdaten!$J$9:$J$26,Stammdaten!$I$9:$I$26,AG12)=0),VLOOKUP(TEXT(AG12,"TTT"),Stammdaten!$B$20:$F$26,5,FALSE),0))) -> 0 | AJ12: =DATE(Jahr,MONTH(AJ$4),$B12) -> 45999 | AK12: =IF($B12>DAY(EOMONTH(AJ$4,0)),"",SUMIFS(INDIRECT(TEXT(AJ12,"MMM")&"!$L$9:$L$999"),INDIRECT(TEXT(AJ12,"MMM")&"!$B$9:$B$999"),AJ12)+SUMIFS(Abwesenheit!$J$3:$J$199,Abwesenheit!$D$3:$D$199,AJ12)) -> 0 | AL12: =IF($B12>DAY(EOMONTH(AJ$4,0)),"",IF(OR(AJ12<IF(YEAR(Eintritt)<Jahr,DATE(Jahr,1,1),Eintritt),AJ12>IF(Austritt="",DATE(Jahr,12,31),Austritt)),0,VLOOKUP(TEXT(AJ12,"TTT"),Stammdaten!$B$20:$F$26,5,FALSE)-IF(ISERROR(VLOOKUP(AJ12,Stammdaten!$I$9:$J$26,2,FALSE)),0,SUMIFS(Stammdaten!$J$9:$J$26,Stammdaten!$I$9:$I$26,AJ12)/24))) -> 0 | AM12: 8
